Workbook
Name TICKET: 'Configuración'!$B$10
Name COM: 'Configuración'!$B$12
Name COM_SHOP: 'Configuración'!$B$13
Name IMP_META: 'Configuración'!$B$14
Name CPA_BE: 'Configuración'!$B$16
Name ROAS_BE: 'Configuración'!$B$17
Name MIN_VENTAS: 'Configuración'!$B$20
Name K_SIN_VENTA: 'Configuración'!$B$21
Name K_CARO: 'Configuración'!$B$22
Name TOL: 'Configuración'!$B$23

Sheet Resumen
A1: Control de inversión en Meta
A3: Gasto en Meta | B3: Gasto + impuestos | C3: Valor de compras | D3: Ganancia neta | E3: ROAS | F3: Compras | G3: CPA | H3: CPA de equilibrio
A4: =SUM(Registro!$E$2:$E$1501) | B4: =A4*(1+IMP_META) | C4: =SUM(Registro!$I$2:$I$1501) | D4: =C4*(1-COM-COM_SHOP)-B4 | E4: =IF(A4>0,C4/A4,"") | F4: =SUM(Registro!$H$2:$H$1501) | G4: =IF(F4>0,A4/F4,"") | H4: =CPA_BE
A5: Ganancia neta = valor de compras − comisiones (Mercado Pago + Shopify) − gasto con impuestos.
A7: Por fase
A8: Fase | B8: Gasto | C8: Valor de compras | D8: Ganancia neta | E8: ROAS | F8: Compras | G8: CPA | H8: CTR
A9: Test ABO | B9: =SUMIFS(Registro!$E$2:$E$1501,Registro!$B$2:$B$1501,A9) | C9: =SUMIFS(Registro!$I$2:$I$1501,Registro!$B$2:$B$1501,A9) | D9: =C9*(1-COM-COM_SHOP)-B9*(1+IMP_META) | E9: =IF(B9>0,C9/B9,"") | F9: =SUMIFS(Registro!$H$2:$H$1501,Registro!$B$2:$B$1501,A9) | G9: =IF(F9>0,B9/F9,"") | H9: =IF(SUMIFS(Registro!$F$2:$F$1501,Registro!$B$2:$B$1501,A9)>0,SUMIFS(Registro!$G$2:$G$1501,Registro!$B$2:$B$1501,A9)/SUMIFS(Registro!$F$2:$F$1501,Registro!$B$2:$B$1501,A9),"")
A10: Escala CBO | B10: =SUMIFS(Registro!$E$2:$E$1501,Registro!$B$2:$B$1501,A10) | C10: =SUMIFS(Registro!$I$2:$I$1501,Registro!$B$2:$B$1501,A10) | D10: =C10*(1-COM-COM_SHOP)-B10*(1+IMP_META) | E10: =IF(B10>0,C10/B10,"") | F10: =SUMIFS(Registro!$H$2:$H$1501,Registro!$B$2:$B$1501,A10) | G10: =IF(F10>0,B10/F10,"") | H10: =IF(SUMIFS(Registro!$F$2:$F$1501,Registro!$B$2:$B$1501,A10)>0,SUMIFS(Registro!$G$2:$G$1501,Registro!$B$2:$B$1501,A10)/SUMIFS(Registro!$F$2:$F$1501,Registro!$B$2:$B$1501,A10),"")
A13: Por ángulo de venta
A14: Ángulo | B14: Gasto | C14: Valor de compras | D14: Ganancia neta | E14: ROAS | F14: Compras | G14: CPA | H14: CTR
A15: =IF('Configuración'!A26="","",'Configuración'!A26) | B15: =SUMIFS(Registro!$E$2:$E$1501,Registro!$D$2:$D$1501,A15) | C15: =SUMIFS(Registro!$I$2:$I$1501,Registro!$D$2:$D$1501,A15) | D15: =C15*(1-COM-COM_SHOP)-B15*(1+IMP_META) | E15: =IF(B15>0,C15/B15,"") | F15: =SUMIFS(Registro!$H$2:$H$1501,Registro!$D$2:$D$1501,A15) | G15: =IF(F15>0,B15/F15,"") | H15: =IF(SUMIFS(Registro!$F$2:$F$1501,Registro!$D$2:$D$1501,A15)>0,SUMIFS(Registro!$G$2:$G$1501,Registro!$D$2:$D$1501,A15)/SUMIFS(Registro!$F$2:$F$1501,Registro!$D$2:$D$1501,A15),"")
A16: =IF('Configuración'!A27="","",'Configuración'!A27) | B16: =SUMIFS(Registro!$E$2:$E$1501,Registro!$D$2:$D$1501,A16) | C16: =SUMIFS(Registro!$I$2:$I$1501,Registro!$D$2:$D$1501,A16) | D16: =C16*(1-COM-COM_SHOP)-B16*(1+IMP_META) | E16: =IF(B16>0,C16/B16,"") | F16: =SUMIFS(Registro!$H$2:$H$1501,Registro!$D$2:$D$1501,A16) | G16: =IF(F16>0,B16/F16,"") | H16: =IF(SUMIFS(Registro!$F$2:$F$1501,Registro!$D$2:$D$1501,A16)>0,SUMIFS(Registro!$G$2:$G$1501,Registro!$D$2:$D$1501,A16)/SUMIFS(Registro!$F$2:$F$1501,Registro!$D$2:$D$1501,A16),"")
A17: =IF('Configuración'!A28="","",'Configuración'!A28) | B17: =SUMIFS(Registro!$E$2:$E$1501,Registro!$D$2:$D$1501,A17) | C17: =SUMIFS(Registro!$I$2:$I$1501,Registro!$D$2:$D$1501,A17) | D17: =C17*(1-COM-COM_SHOP)-B17*(1+IMP_META) | E17: =IF(B17>0,C17/B17,"") | F17: =SUMIFS(Registro!$H$2:$H$1501,Registro!$D$2:$D$1501,A17) | G17: =IF(F17>0,B17/F17,"") | H17: =IF(SUMIFS(Registro!$F$2:$F$1501,Registro!$D$2:$D$1501,A17)>0,SUMIFS(Registro!$G$2:$G$1501,Registro!$D$2:$D$1501,A17)/SUMIFS(Registro!$F$2:$F$1501,Registro!$D$2:$D$1501,A17),"")
A18: =IF('Configuración'!A29="","",'Configuración'!A29) | B18: =SUMIFS(Registro!$E$2:$E$1501,Registro!$D$2:$D$1501,A18) | C18: =SUMIFS(Registro!$I$2:$I$1501,Registro!$D$2:$D$1501,A18) | D18: =C18*(1-COM-COM_SHOP)-B18*(1+IMP_META) | E18: =IF(B18>0,C18/B18,"") | F18: =SUMIFS(Registro!$H$2:$H$1501,Registro!$D$2:$D$1501,A18) | G18: =IF(F18>0,B18/F18,"") | H18: =IF(SUMIFS(Registro!$F$2:$F$1501,Registro!$D$2:$D$1501,A18)>0,SUMIFS(Registro!$G$2:$G$1501,Registro!$D$2:$D$1501,A18)/SUMIFS(Registro!$F$2:$F$1501,Registro!$D$2:$D$1501,A18),"")
A19: =IF('Configuración'!A30="","",'Configuración'!A30) | B19: =SUMIFS(Registro!$E$2:$E$1501,Registro!$D$2:$D$1501,A19) | C19: =SUMIFS(Registro!$I$2:$I$1501,Registro!$D$2:$D$1501,A19) | D19: =C19*(1-COM-COM_SHOP)-B19*(1+IMP_META) | E19: =IF(B19>0,C19/B19,"") | F19: =SUMIFS(Registro!$H$2:$H$1501,Registro!$D$2:$D$1501,A19) | G19: =IF(F19>0,B19/F19,"") | H19: =IF(SUMIFS(Registro!$F$2:$F$1501,Registro!$D$2:$D$1501,A19)>0,SUMIFS(Registro!$G$2:$G$1501,Registro!$D$2:$D$1501,A19)/SUMIFS(Registro!$F$2:$F$1501,Registro!$D$2:$D$1501,A19),"")
A20: =IF('Configuración'!A31="","",'Configuración'!A31) | B20: =SUMIFS(Registro!$E$2:$E$1501,Registro!$D$2:$D$1501,A20) | C20: =SUMIFS(Registro!$I$2:$I$1501,Registro!$D$2:$D$1501,A20) | D20: =C20*(1-COM-COM_SHOP)-B20*(1+IMP_META) | E20: =IF(B20>0,C20/B20,"") | F20: =SUMIFS(Registro!$H$2:$H$1501,Registro!$D$2:$D$1501,A20) | G20: =IF(F20>0,B20/F20,"") | H20: =IF(SUMIFS(Registro!$F$2:$F$1501,Registro!$D$2:$D$1501,A20)>0,SUMIFS(Registro!$G$2:$G$1501,Registro!$D$2:$D$1501,A20)/SUMIFS(Registro!$F$2:$F$1501,Registro!$D$2:$D$1501,A20),"")
A21: =IF('Configuración'!A32="","",'Configuración'!A32) | B21: =SUMIFS(Registro!$E$2:$E$1501,Registro!$D$2:$D$1501,A21) | C21: =SUMIFS(Registro!$I$2:$I$1501,Registro!$D$2:$D$1501,A21) | D21: =C21*(1-COM-COM_SHOP)-B21*(1+IMP_META) | E21: =IF(B21>0,C21/B21,"") | F21: =SUMIFS(Registro!$H$2:$H$1501,Registro!$D$2:$D$1501,A21) | G21: =IF(F21>0,B21/F21,"") | H21: =IF(SUMIFS(Registro!$F$2:$F$1501,Registro!$D$2:$D$1501,A21)>0,SUMIFS(Registro!$G$2:$G$1501,Registro!$D$2:$D$1501,A21)/SUMIFS(Registro!$F$2:$F$1501,Registro!$D$2:$D$1501,A21),"")
A22: =IF('Configuración'!A33="","",'Configuración'!A33) | B22: =SUMIFS(Registro!$E$2:$E$1501,Registro!$D$2:$D$1501,A22) | C22: =SUMIFS(Registro!$I$2:$I$1501,Registro!$D$2:$D$1501,A22) | D22: =C22*(1-COM-COM_SHOP)-B22*(1+IMP_META) | E22: =IF(B22>0,C22/B22,"") | F22: =SUMIFS(Registro!$H$2:$H$1501,Registro!$D$2:$D$1501,A22) | G22: =IF(F22>0,B22/F22,"") | H22: =IF(SUMIFS(Registro!$F$2:$F$1501,Registro!$D$2:$D$1501,A22)>0,SUMIFS(Registro!$G$2:$G$1501,Registro!$D$2:$D$1501,A22)/SUMIFS(Registro!$F$2:$F$1501,Registro!$D$2:$D$1501,A22),"")
A23: =IF('Configuración'!A34="","",'Configuración'!A34) | B23: =SUMIFS(Registro!$E$2:$E$1501,Registro!$D$2:$D$1501,A23) | C23: =SUMIFS(Registro!$I$2:$I$1501,Registro!$D$2:$D$1501,A23) | D23: =C23*(1-COM-COM_SHOP)-B23*(1+IMP_META) | E23: =IF(B23>0,C23/B23,"") | F23: =SUMIFS(Registro!$H$2:$H$1501,Registro!$D$2:$D$1501,A23) | G23: =IF(F23>0,B23/F23,"") | H23: =IF(SUMIFS(Registro!$F$2:$F$1501,Registro!$D$2:$D$1501,A23)>0,SUMIFS(Registro!$G$2:$G$1501,Registro!$D$2:$D$1501,A23)/SUMIFS(Registro!$F$2:$F$1501,Registro!$D$2:$D$1501,A23),"")
A24: =IF('Configuración'!A35="","",'Configuración'!A35) | B24: =SUMIFS(Registro!$E$2:$E$1501,Registro!$D$2:$D$1501,A24) | C24: =SUMIFS(Registro!$I$2:$I$1501,Registro!$D$2:$D$1501,A24) | D24: =C24*(1-COM-COM_SHOP)-B24*(1+IMP_META) | E24: =IF(B24>0,C24/B24,"") | F24: =SUMIFS(Registro!$H$2:$H$1501,Registro!$D$2:$D$1501,A24) | G24: =IF(F24>0,B24/F24,"") | H24: =IF(SUMIFS(Registro!$F$2:$F$1501,Registro!$D$2:$D$1501,A24)>0,SUMIFS(Registro!$G$2:$G$1501,Registro!$D$2:$D$1501,A24)/SUMIFS(Registro!$F$2:$F$1501,Registro!$D$2:$D$1501,A24),"")
A25: =IF('Configuración'!A36="","",'Configuración'!A36) | B25: =SUMIFS(Registro!$E$2:$E$1501,Registro!$D$2:$D$1501,A25) | C25: =SUMIFS(Registro!$I$2:$I$1501,Registro!$D$2:$D$1501,A25) | D25: =C25*(1-COM-COM_SHOP)-B25*(1+IMP_META) | E25: =IF(B25>0,C25/B25,"") | F25: =SUMIFS(Registro!$H$2:$H$1501,Registro!$D$2:$D$1501,A25) | G25: =IF(F25>0,B25/F25,"") | H25: =IF(SUMIFS(Registro!$F$2:$F$1501,Registro!$D$2:$D$1501,A25)>0,SUMIFS(Registro!$G$2:$G$1501,Registro!$D$2:$D$1501,A25)/SUMIFS(Registro!$F$2:$F$1501,Registro!$D$2:$D$1501,A25),"")
A26: =IF('Configuración'!A37="","",'Configuración'!A37) | B26: =SUMIFS(Registro!$E$2:$E$1501,Registro!$D$2:$D$1501,A26) | C26: =SUMIFS(Registro!$I$2:$I$1501,Registro!$D$2:$D$1501,A26) | D26: =C26*(1-COM-COM_SHOP)-B26*(1+IMP_META) | E26: =IF(B26>0,C26/B26,"") | F26: =SUMIFS(Registro!$H$2:$H$1501,Registro!$D$2:$D$1501,A26) | G26: =IF(F26>0,B26/F26,"") | H26: =IF(SUMIFS(Registro!$F$2:$F$1501,Registro!$D$2:$D$1501,A26)>0,SUMIFS(Registro!$G$2:$G$1501,Registro!$D$2:$D$1501,A26)/SUMIFS(Registro!$F$2:$F$1501,Registro!$D$2:$D$1501,A26),"")
... A29: =IF('Configuración'!A40="","",'Configuración'!A40) | B29: =SUMIFS(Registro!$E$2:$E$1501,Registro!$D$2:$D$1501,A29) | C29: =SUMIFS(Registro!$I$2:$I$1501,Registro!$D$2:$D$1501,A29) | D29: =C29*(1-COM-COM_SHOP)-B29*(1+IMP_META) | E29: =IF(B29>0,C29/B29,"") | F29: =SUMIFS(Registro!$H$2:$H$1501,Registro!$D$2:$D$1501,A29) | G29: =IF(F29>0,B29/F29,"") | H29: =IF(SUMIFS(Registro!$F$2:$F$1501,Registro!$D$2:$D$1501,A29)>0,SUMIFS(Registro!$G$2:$G$1501,Registro!$D$2:$D$1501,A29)/SUMIFS(Registro!$F$2:$F$1501,Registro!$D$2:$D$1501,A29),"")
A32: Por mes | D32: Primer mes: | E32: 46266
A33: Mes | B33: Gasto | C33: Valor de compras | D33: Ganancia neta | E33: ROAS | F33: Compras | G33: CPA | H33: CTR
A34: =$E$32 | B34: =SUMIFS(Registro!$E$2:$E$1501,Registro!$A$2:$A$1501,">="&A34,Registro!$A$2:$A$1501,"<"&EDATE(A34,1)) | C34: =SUMIFS(Registro!$I$2:$I$1501,Registro!$A$2:$A$1501,">="&A34,Registro!$A$2:$A$1501,"<"&EDATE(A34,1)) | D34: =C34*(1-COM-COM_SHOP)-B34*(1+IMP_META) | E34: =IF(B34>0,C34/B34,"") | F34: =SUMIFS(Registro!$H$2:$H$1501,Registro!$A$2:$A$1501,">="&A34,Registro!$A$2:$A$1501,"<"&EDATE(A34,1)) | G34: =IF(F34>0,B34/F34,"") | H34: =IF(SUMIFS(Registro!$F$2:$F$1501,Registro!$A$2:$A$1501,">="&A34,Registro!$A$2:$A$1501,"<"&EDATE(A34,1))>0,SUMIFS(Registro!$G$2:$G$1501,Registro!$A$2:$A$1501,">="&A34,Registro!$A$2:$A$1501,"<"&EDATE(A34,1))/SUMIFS(Registro!$F$2:$F$1501,Registro!$A$2:$A$1501,">="&A34,Registro!$A$2:$A$1501,"<"&EDATE(A34,1)),"")
A35: =EDATE(A34,1) | B35: =SUMIFS(Registro!$E$2:$E$1501,Registro!$A$2:$A$1501,">="&A35,Registro!$A$2:$A$1501,"<"&EDATE(A35,1)) | C35: =SUMIFS(Registro!$I$2:$I$1501,Registro!$A$2:$A$1501,">="&A35,Registro!$A$2:$A$1501,"<"&EDATE(A35,1)) | D35: =C35*(1-COM-COM_SHOP)-B35*(1+IMP_META) | E35: =IF(B35>0,C35/B35,"") | F35: =SUMIFS(Registro!$H$2:$H$1501,Registro!$A$2:$A$1501,">="&A35,Registro!$A$2:$A$1501,"<"&EDATE(A35,1)) | G35: =IF(F35>0,B35/F35,"") | H35: =IF(SUMIFS(Registro!$F$2:$F$1501,Registro!$A$2:$A$1501,">="&A35,Registro!$A$2:$A$1501,"<"&EDATE(A35,1))>0,SUMIFS(Registro!$G$2:$G$1501,Registro!$A$2:$A$1501,">="&A35,Registro!$A$2:$A$1501,"<"&EDATE(A35,1))/SUMIFS(Registro!$F$2:$F$1501,Registro!$A$2:$A$1501,">="&A35,Registro!$A$2:$A$1501,"<"&EDATE(A35,1)),"")
A36: =EDATE(A35,1) | B36: =SUMIFS(Registro!$E$2:$E$1501,Registro!$A$2:$A$1501,">="&A36,Registro!$A$2:$A$1501,"<"&EDATE(A36,1)) | C36: =SUMIFS(Registro!$I$2:$I$1501,Registro!$A$2:$A$1501,">="&A36,Registro!$A$2:$A$1501,"<"&EDATE(A36,1)) | D36: =C36*(1-COM-COM_SHOP)-B36*(1+IMP_META) | E36: =IF(B36>0,C36/B36,"") | F36: =SUMIFS(Registro!$H$2:$H$1501,Registro!$A$2:$A$1501,">="&A36,Registro!$A$2:$A$1501,"<"&EDATE(A36,1)) | G36: =IF(F36>0,B36/F36,"") | H36: =IF(SUMIFS(Registro!$F$2:$F$1501,Registro!$A$2:$A$1501,">="&A36,Registro!$A$2:$A$1501,"<"&EDATE(A36,1))>0,SUMIFS(Registro!$G$2:$G$1501,Registro!$A$2:$A$1501,">="&A36,Registro!$A$2:$A$1501,"<"&EDATE(A36,1))/SUMIFS(Registro!$F$2:$F$1501,Registro!$A$2:$A$1501,">="&A36,Registro!$A$2:$A$1501,"<"&EDATE(A36,1)),"")
A37: =EDATE(A36,1) | B37: =SUMIFS(Registro!$E$2:$E$1501,Registro!$A$2:$A$1501,">="&A37,Registro!$A$2:$A$1501,"<"&EDATE(A37,1)) | C37: =SUMIFS(Registro!$I$2:$I$1501,Registro!$A$2:$A$1501,">="&A37,Registro!$A$2:$A$1501,"<"&EDATE(A37,1)) | D37: =C37*(1-COM-COM_SHOP)-B37*(1+IMP_META) | E37: =IF(B37>0,C37/B37,"") | F37: =SUMIFS(Registro!$H$2:$H$1501,Registro!$A$2:$A$1501,">="&A37,Registro!$A$2:$A$1501,"<"&EDATE(A37,1)) | G37: =IF(F37>0,B37/F37,"") | H37: =IF(SUMIFS(Registro!$F$2:$F$1501,Registro!$A$2:$A$1501,">="&A37,Registro!$A$2:$A$1501,"<"&EDATE(A37,1))>0,SUMIFS(Registro!$G$2:$G$1501,Registro!$A$2:$A$1501,">="&A37,Registro!$A$2:$A$1501,"<"&EDATE(A37,1))/SUMIFS(Registro!$F$2:$F$1501,Registro!$A$2:$A$1501,">="&A37,Registro!$A$2:$A$1501,"<"&EDATE(A37,1)),"")
A38: =EDATE(A37,1) | B38: =SUMIFS(Registro!$E$2:$E$1501,Registro!$A$2:$A$1501,">="&A38,Registro!$A$2:$A$1501,"<"&EDATE(A38,1)) | C38: =SUMIFS(Registro!$I$2:$I$1501,Registro!$A$2:$A$1501,">="&A38,Registro!$A$2:$A$1501,"<"&EDATE(A38,1)) | D38: =C38*(1-COM-COM_SHOP)-B38*(1+IMP_META) | E38: =IF(B38>0,C38/B38,"") | F38: =SUMIFS(Registro!$H$2:$H$1501,Registro!$A$2:$A$1501,">="&A38,Registro!$A$2:$A$1501,"<"&EDATE(A38,1)) | G38: =IF(F38>0,B38/F38,"") | H38: =IF(SUMIFS(Registro!$F$2:$F$1501,Registro!$A$2:$A$1501,">="&A38,Registro!$A$2:$A$1501,"<"&EDATE(A38,1))>0,SUMIFS(Registro!$G$2:$G$1501,Registro!$A$2:$A$1501,">="&A38,Registro!$A$2:$A$1501,"<"&EDATE(A38,1))/SUMIFS(Registro!$F$2:$F$1501,Registro!$A$2:$A$1501,">="&A38,Registro!$A$2:$A$1501,"<"&EDATE(A38,1)),"")
A39: =EDATE(A38,1) | B39: =SUMIFS(Registro!$E$2:$E$1501,Registro!$A$2:$A$1501,">="&A39,Registro!$A$2:$A$1501,"<"&EDATE(A39,1)) | C39: =SUMIFS(Registro!$I$2:$I$1501,Registro!$A$2:$A$1501,">="&A39,Registro!$A$2:$A$1501,"<"&EDATE(A39,1)) | D39: =C39*(1-COM-COM_SHOP)-B39*(1+IMP_META) | E39: =IF(B39>0,C39/B39,"") | F39: =SUMIFS(Registro!$H$2:$H$1501,Registro!$A$2:$A$1501,">="&A39,Registro!$A$2:$A$1501,"<"&EDATE(A39,1)) | G39: =IF(F39>0,B39/F39,"") | H39: =IF(SUMIFS(Registro!$F$2:$F$1501,Registro!$A$2:$A$1501,">="&A39,Registro!$A$2:$A$1501,"<"&EDATE(A39,1))>0,SUMIFS(Registro!$G$2:$G$1501,Registro!$A$2:$A$1501,">="&A39,Registro!$A$2:$A$1501,"<"&EDATE(A39,1))/SUMIFS(Registro!$F$2:$F$1501,Registro!$A$2:$A$1501,">="&A39,Registro!$A$2:$A$1501,"<"&EDATE(A39,1)),"")
A40: =EDATE(A39,1) | B40: =SUMIFS(Registro!$E$2:$E$1501,Registro!$A$2:$A$1501,">="&A40,Registro!$A$2:$A$1501,"<"&EDATE(A40,1)) | C40: =SUMIFS(Registro!$I$2:$I$1501,Registro!$A$2:$A$1501,">="&A40,Registro!$A$2:$A$1501,"<"&EDATE(A40,1)) | D40: =C40*(1-COM-COM_SHOP)-B40*(1+IMP_META) | E40: =IF(B40>0,C40/B40,"") | F40: =SUMIFS(Registro!$H$2:$H$1501,Registro!$A$2:$A$1501,">="&A40,Registro!$A$2:$A$1501,"<"&EDATE(A40,1)) | G40: =IF(F40>0,B40/F40,"") | H40: =IF(SUMIFS(Registro!$F$2:$F$1501,Registro!$A$2:$A$1501,">="&A40,Registro!$A$2:$A$1501,"<"&EDATE(A40,1))>0,SUMIFS(Registro!$G$2:$G$1501,Registro!$A$2:$A$1501,">="&A40,Registro!$A$2:$A$1501,"<"&EDATE(A40,1))/SUMIFS(Registro!$F$2:$F$1501,Registro!$A$2:$A$1501,">="&A40,Registro!$A$2:$A$1501,"<"&EDATE(A40,1)),"")
A41: =EDATE(A40,1) | B41: =SUMIFS(Registro!$E$2:$E$1501,Registro!$A$2:$A$1501,">="&A41,Registro!$A$2:$A$1501,"<"&EDATE(A41,1)) | C41: =SUMIFS(Registro!$I$2:$I$1501,Registro!$A$2:$A$1501,">="&A41,Registro!$A$2:$A$1501,"<"&EDATE(A41,1)) | D41: =C41*(1-COM-COM_SHOP)-B41*(1+IMP_META) | E41: =IF(B41>0,C41/B41,"") | F41: =SUMIFS(Registro!$H$2:$H$1501,Registro!$A$2:$A$1501,">="&A41,Registro!$A$2:$A$1501,"<"&EDATE(A41,1)) | G41: =IF(F41>0,B41/F41,"") | H41: =IF(SUMIFS(Registro!$F$2:$F$1501,Registro!$A$2:$A$1501,">="&A41,Registro!$A$2:$A$1501,"<"&EDATE(A41,1))>0,SUMIFS(Registro!$G$2:$G$1501,Registro!$A$2:$A$1501,">="&A41,Registro!$A$2:$A$1501,"<"&EDATE(A41,1))/SUMIFS(Registro!$F$2:$F$1501,Registro!$A$2:$A$1501,">="&A41,Registro!$A$2:$A$1501,"<"&EDATE(A41,1)),"")
A42: =EDATE(A41,1) | B42: =SUMIFS(Registro!$E$2:$E$1501,Registro!$A$2:$A$1501,">="&A42,Registro!$A$2:$A$1501,"<"&EDATE(A42,1)) | C42: =SUMIFS(Registro!$I$2:$I$1501,Registro!$A$2:$A$1501,">="&A42,Registro!$A$2:$A$1501,"<"&EDATE(A42,1)) | D42: =C42*(1-COM-COM_SHOP)-B42*(1+IMP_META) | E42: =IF(B42>0,C42/B42,"") | F42: =SUMIFS(Registro!$H$2:$H$1501,Registro!$A$2:$A$1501,">="&A42,Registro!$A$2:$A$1501,"<"&EDATE(A42,1)) | G42: =IF(F42>0,B42/F42,"") | H42: =IF(SUMIFS(Registro!$F$2:$F$1501,Registro!$A$2:$A$1501,">="&A42,Registro!$A$2:$A$1501,"<"&EDATE(A42,1))>0,SUMIFS(Registro!$G$2:$G$1501,Registro!$A$2:$A$1501,">="&A42,Registro!$A$2:$A$1501,"<"&EDATE(A42,1))/SUMIFS(Registro!$F$2:$F$1501,Registro!$A$2:$A$1501,">="&A42,Registro!$A$2:$A$1501,"<"&EDATE(A42,1)),"")
A43: =EDATE(A42,1) | B43: =SUMIFS(Registro!$E$2:$E$1501,Registro!$A$2:$A$1501,">="&A43,Registro!$A$2:$A$1501,"<"&EDATE(A43,1)) | C43: =SUMIFS(Registro!$I$2:$I$1501,Registro!$A$2:$A$1501,">="&A43,Registro!$A$2:$A$1501,"<"&EDATE(A43,1)) | D43: =C43*(1-COM-COM_SHOP)-B43*(1+IMP_META) | E43: =IF(B43>0,C43/B43,"") | F43: =SUMIFS(Registro!$H$2:$H$1501,Registro!$A$2:$A$1501,">="&A43,Registro!$A$2:$A$1501,"<"&EDATE(A43,1)) | G43: =IF(F43>0,B43/F43,"") | H43: =IF(SUMIFS(Registro!$F$2:$F$1501,Registro!$A$2:$A$1501,">="&A43,Registro!$A$2:$A$1501,"<"&EDATE(A43,1))>0,SUMIFS(Registro!$G$2:$G$1501,Registro!$A$2:$A$1501,">="&A43,Registro!$A$2:$A$1501,"<"&EDATE(A43,1))/SUMIFS(Registro!$F$2:$F$1501,Registro!$A$2:$A$1501,">="&A43,Registro!$A$2:$A$1501,"<"&EDATE(A43,1)),"")
A44: =EDATE(A43,1) | B44: =SUMIFS(Registro!$E$2:$E$1501,Registro!$A$2:$A$1501,">="&A44,Registro!$A$2:$A$1501,"<"&EDATE(A44,1)) | C44: =SUMIFS(Registro!$I$2:$I$1501,Registro!$A$2:$A$1501,">="&A44,Registro!$A$2:$A$1501,"<"&EDATE(A44,1)) | D44: =C44*(1-COM-COM_SHOP)-B44*(1+IMP_META) | E44: =IF(B44>0,C44/B44,"") | F44: =SUMIFS(Registro!$H$2:$H$1501,Registro!$A$2:$A$1501,">="&A44,Registro!$A$2:$A$1501,"<"&EDATE(A44,1)) | G44: =IF(F44>0,B44/F44,"") | H44: =IF(SUMIFS(Registro!$F$2:$F$1501,Registro!$A$2:$A$1501,">="&A44,Registro!$A$2:$A$1501,"<"&EDATE(A44,1))>0,SUMIFS(Registro!$G$2:$G$1501,Registro!$A$2:$A$1501,">="&A44,Registro!$A$2:$A$1501,"<"&EDATE(A44,1))/SUMIFS(Registro!$F$2:$F$1501,Registro!$A$2:$A$1501,">="&A44,Registro!$A$2:$A$1501,"<"&EDATE(A44,1)),"")
A45: =EDATE(A44,1) | B45: =SUMIFS(Registro!$E$2:$E$1501,Registro!$A$2:$A$1501,">="&A45,Registro!$A$2:$A$1501,"<"&EDATE(A45,1)) | C45: =SUMIFS(Registro!$I$2:$I$1501,Registro!$A$2:$A$1501,">="&A45,Registro!$A$2:$A$1501,"<"&EDATE(A45,1)) | D45: =C45*(1-COM-COM_SHOP)-B45*(1+IMP_META) | E45: =IF(B45>0,C45/B45,"") | F45: =SUMIFS(Registro!$H$2:$H$1501,Registro!$A$2:$A$1501,">="&A45,Registro!$A$2:$A$1501,"<"&EDATE(A45,1)) | G45: =IF(F45>0,B45/F45,"") | H45: =IF(SUMIFS(Registro!$F$2:$F$1501,Registro!$A$2:$A$1501,">="&A45,Registro!$A$2:$A$1501,"<"&EDATE(A45,1))>0,SUMIFS(Registro!$G$2:$G$1501,Registro!$A$2:$A$1501,">="&A45,Registro!$A$2:$A$1501,"<"&EDATE(A45,1))/SUMIFS(Registro!$F$2:$F$1501,Registro!$A$2:$A$1501,">="&A45,Registro!$A$2:$A$1501,"<"&EDATE(A45,1)),"")
A48: Últimas 8 semanas (lunes a domingo)
A49: Semana del | B49: Gasto | C49: Valor de compras | D49: Ganancia neta | E49: ROAS | F49: Compras | G49: CPA | H49: CTR
A50: =TODAY()-WEEKDAY(TODAY(),3)-49 | B50: =SUMIFS(Registro!$E$2:$E$1501,Registro!$A$2:$A$1501,">="&A50,Registro!$A$2:$A$1501,"<"&(A50+7)) | C50: =SUMIFS(Registro!$I$2:$I$1501,Registro!$A$2:$A$1501,">="&A50,Registro!$A$2:$A$1501,"<"&(A50+7)) | D50: =C50*(1-COM-COM_SHOP)-B50*(1+IMP_META) | E50: =IF(B50>0,C50/B50,"") | F50: =SUMIFS(Registro!$H$2:$H$1501,Registro!$A$2:$A$1501,">="&A50,Registro!$A$2:$A$1501,"<"&(A50+7)) | G50: =IF(F50>0,B50/F50,"") | H50: =IF(SUMIFS(Registro!$F$2:$F$1501,Registro!$A$2:$A$1501,">="&A50,Registro!$A$2:$A$1501,"<"&(A50+7))>0,SUMIFS(Registro!$G$2:$G$1501,Registro!$A$2:$A$1501,">="&A50,Registro!$A$2:$A$1501,"<"&(A50+7))/SUMIFS(Registro!$F$2:$F$1501,Registro!$A$2:$A$1501,">="&A50,Registro!$A$2:$A$1501,"<"&(A50+7)),"")
...

Sheet Anuncios
A1: Tablero de anuncios
A2: ="CPA de equilibrio: "&TEXT(CPA_BE,"$ #,##0")&" · ROAS de equilibrio: "&TEXT(ROAS_BE,"0.00")&"x"
A3: Cargá acá cada anuncio (nombre tal cual lo vas a elegir en Registro) y su ángulo. Todo lo demás se calcula.
A4: ANUNCIO | F4: TEST ABO | O4: ESCALA CBO | U4: TOTAL
A5: Anuncio | B5: Ángulo | C5: Formato | D5: Primer día | E5: Días con datos | F5: Gasto | G5: Gastado (veces CPA BE) | H5: Compras | I5: CPA | J5: CPA vs BE | K5: ROAS | L5: Ganancia neta | M5: CTR | N5: ESTADO TEST | O5: Gasto | P5: Compras | Q5: CPA | R5: ROAS | S5: Ganancia neta | T5: Estado escala | U5: Ganancia neta total
A6: AD01 - Ahorro de tiempo | B6: Ahorro de tiempo | C6: Video | D6: =IF(COUNTIFS(Registro!$C$2:$C$1501,$A6)=0,"",_xlfn.MINIFS(Registro!$A$2:$A$1501,Registro!$C$2:$C$1501,$A6)) | E6: =IF($A6="","",COUNTIFS(Registro!$C$2:$C$1501,$A6,Registro!$E$2:$E$1501,">0")) | F6: =IF($A6="","",SUMIFS(Registro!$E$2:$E$1501,Registro!$C$2:$C$1501,$A6,Registro!$B$2:$B$1501,"Test ABO")) | G6: =IF($A6="","",F6/CPA_BE) | H6: =IF($A6="","",SUMIFS(Registro!$H$2:$H$1501,Registro!$C$2:$C$1501,$A6,Registro!$B$2:$B$1501,"Test ABO")) | I6: =IF(N(H6)>0,F6/H6,"") | J6: =IF(N(H6)>0,I6/CPA_BE-1,"") | K6: =IF(N(F6)>0,SUMIFS(Registro!$I$2:$I$1501,Registro!$C$2:$C$1501,$A6,Registro!$B$2:$B$1501,"Test ABO")/F6,"") | L6: =IF(N(F6)>0,SUMIFS(Registro!$I$2:$I$1501,Registro!$C$2:$C$1501,$A6,Registro!$B$2:$B$1501,"Test ABO")*(1-COM-COM_SHOP)-F6*(1+IMP_META),"") | M6: =IF(SUMIFS(Registro!$F$2:$F$1501,Registro!$C$2:$C$1501,$A6,Registro!$B$2:$B$1501,"Test ABO")>0,SUMIFS(Registro!$G$2:$G$1501,Registro!$C$2:$C$1501,$A6,Registro!$B$2:$B$1501,"Test ABO")/SUMIFS(Registro!$F$2:$F$1501,Registro!$C$2:$C$1501,$A6,Registro!$B$2:$B$1501,"Test ABO"),"") | N6: =IF($A6="","",IF(N(F6)=0,"Sin datos",IF(AND(H6>=MIN_VENTAS,N(I6)<=CPA_BE),"GANADOR → pasar a CBO",IF(AND(H6=0,F6>=K_SIN_VENTA*CPA_BE),"APAGAR (sin ventas)",IF(AND(H6>0,F6>=K_CARO*CPA_BE,N(I6)>CPA_BE*(1+TOL)),"APAGAR (CPA alto)",IF(AND(H6>0,N(I6)<=CPA_BE*(1+TOL)),"Prometedor / cerca del BE","Juntando datos")))))) | O6: =IF($A6="","",SUMIFS(Registro!$E$2:$E$1501,Registro!$C$2:$C$1501,$A6,Registro!$B$2:$B$1501,"Escala CBO")) | P6: =IF($A6="","",SUMIFS(Registro!$H$2:$H$1501,Registro!$C$2:$C$1501,$A6,Registro!$B$2:$B$1501,"Escala CBO")) | Q6: =IF(N(P6)>0,O6/P6,"") | R6: =IF(N(O6)>0,SUMIFS(Registro!$I$2:$I$1501,Registro!$C$2:$C$1501,$A6,Registro!$B$2:$B$1501,"Escala CBO")/O6,"") | S6: =IF(N(O6)>0,SUMIFS(Registro!$I$2:$I$1501,Registro!$C$2:$C$1501,$A6,Registro!$B$2:$B$1501,"Escala CBO")*(1-COM-COM_SHOP)-O6*(1+IMP_META),"") | T6: =IF(N(O6)=0,"",IF(P6=0,IF(O6>=K_SIN_VENTA*CPA_BE,"Sin ventas: revisar","Juntando datos"),IF(Q6<=CPA_BE,"Rentable","No rentable"))) | U6: =IF($A6="","",N(L6)+N(S6))
A7: AD02 - Resultados en los chicos | B7: Resultados en los chicos | C7: Video | D7: =IF(COUNTIFS(Registro!$C$2:$C$1501,$A7)=0,"",_xlfn.MINIFS(Registro!$A$2:$A$1501,Registro!$C$2:$C$1501,$A7)) | E7: =IF($A7="","",COUNTIFS(Registro!$C$2:$C$1501,$A7,Registro!$E$2:$E$1501,">0")) | F7: =IF($A7="","",SUMIFS(Registro!$E$2:$E$1501,Registro!$C$2:$C$1501,$A7,Registro!$B$2:$B$1501,"Test ABO")) | G7: =IF($A7="","",F7/CPA_BE) | H7: =IF($A7="","",SUMIFS(Registro!$H$2:$H$1501,Registro!$C$2:$C$1501,$A7,Registro!$B$2:$B$1501,"Test ABO")) | I7: =IF(N(H7)>0,F7/H7,"") | J7: =IF(N(H7)>0,I7/CPA_BE-1,"") | K7: =IF(N(F7)>0,SUMIFS(Registro!$I$2:$I$1501,Registro!$C$2:$C$1501,$A7,Registro!$B$2:$B$1501,"Test ABO")/F7,"") | L7: =IF(N(F7)>0,SUMIFS(Registro!$I$2:$I$1501,Registro!$C$2:$C$1501,$A7,Registro!$B$2:$B$1501,"Test ABO")*(1-COM-COM_SHOP)-F7*(1+IMP_META),"") | M7: =IF(SUMIFS(Registro!$F$2:$F$1501,Registro!$C$2:$C$1501,$A7,Registro!$B$2:$B$1501,"Test ABO")>0,SUMIFS(Registro!$G$2:$G$1501,Registro!$C$2:$C$1501,$A7,Registro!$B$2:$B$1501,"Test ABO")/SUMIFS(Registro!$F$2:$F$1501,Registro!$C$2:$C$1501,$A7,Registro!$B$2:$B$1501,"Test ABO"),"") | N7: =IF($A7="","",IF(N(F7)=0,"Sin datos",IF(AND(H7>=MIN_VENTAS,N(I7)<=CPA_BE),"GANADOR → pasar a CBO",IF(AND(H7=0,F7>=K_SIN_VENTA*CPA_BE),"APAGAR (sin ventas)",IF(AND(H7>0,F7>=K_CARO*CPA_BE,N(I7)>CPA_BE*(1+TOL)),"APAGAR (CPA alto)",IF(AND(H7>0,N(I7)<=CPA_BE*(1+TOL)),"Prometedor / cerca del BE","Juntando datos")))))) | O7: =IF($A7="","",SUMIFS(Registro!$E$2:$E$1501,Registro!$C$2:$C$1501,$A7,Registro!$B$2:$B$1501,"Escala CBO")) | P7: =IF($A7="","",SUMIFS(Registro!$H$2:$H$1501,Registro!$C$2:$C$1501,$A7,Registro!$B$2:$B$1501,"Escala CBO")) | Q7: =IF(N(P7)>0,O7/P7,"") | R7: =IF(N(O7)>0,SUMIFS(Registro!$I$2:$I$1501,Registro!$C$2:$C$1501,$A7,Registro!$B$2:$B$1501,"Escala CBO")/O7,"") | S7: =IF(N(O7)>0,SUMIFS(Registro!$I$2:$I$1501,Registro!$C$2:$C$1501,$A7,Registro!$B$2:$B$1501,"Escala CBO")*(1-COM-COM_SHOP)-O7*(1+IMP_META),"") | T7: =IF(N(O7)=0,"",IF(P7=0,IF(O7>=K_SIN_VENTA*CPA_BE,"Sin ventas: revisar","Juntando datos"),IF(Q7<=CPA_BE,"Rentable","No rentable"))) | U7: =IF($A7="","",N(L7)+N(S7))
A8: AD03 - Autoridad musicoterapeuta | B8: Autoridad musicoterapeuta | C8: Imagen | D8: =IF(COUNTIFS(Registro!$C$2:$C$1501,$A8)=0,"",_xlfn.MINIFS(Registro!$A$2:$A$1501,Registro!$C$2:$C$1501,$A8)) | E8: =IF($A8="","",COUNTIFS(Registro!$C$2:$C$1501,$A8,Registro!$E$2:$E$1501,">0")) | F8: =IF($A8="","",SUMIFS(Registro!$E$2:$E$1501,Registro!$C$2:$C$1501,$A8,Registro!$B$2:$B$1501,"Test ABO")) | G8: =IF($A8="","",F8/CPA_BE) | H8: =IF($A8="","",SUMIFS(Registro!$H$2:$H$1501,Registro!$C$2:$C$1501,$A8,Registro!$B$2:$B$1501,"Test ABO")) | I8: =IF(N(H8)>0,F8/H8,"") | J8: =IF(N(H8)>0,I8/CPA_BE-1,"") | K8: =IF(N(F8)>0,SUMIFS(Registro!$I$2:$I$1501,Registro!$C$2:$C$1501,$A8,Registro!$B$2:$B$1501,"Test ABO")/F8,"") | L8: =IF(N(F8)>0,SUMIFS(Registro!$I$2:$I$1501,Registro!$C$2:$C$1501,$A8,Registro!$B$2:$B$1501,"Test ABO")*(1-COM-COM_SHOP)-F8*(1+IMP_META),"") | M8: =IF(SUMIFS(Registro!$F$2:$F$1501,Registro!$C$2:$C$1501,$A8,Registro!$B$2:$B$1501,"Test ABO")>0,SUMIFS(Registro!$G$2:$G$1501,Registro!$C$2:$C$1501,$A8,Registro!$B$2:$B$1501,"Test ABO")/SUMIFS(Registro!$F$2:$F$1501,Registro!$C$2:$C$1501,$A8,Registro!$B$2:$B$1501,"Test ABO"),"") | N8: =IF($A8="","",IF(N(F8)=0,"Sin datos",IF(AND(H8>=MIN_VENTAS,N(I8)<=CPA_BE),"GANADOR → pasar a CBO",IF(AND(H8=0,F8>=K_SIN_VENTA*CPA_BE),"APAGAR (sin ventas)",IF(AND(H8>0,F8>=K_CARO*CPA_BE,N(I8)>CPA_BE*(1+TOL)),"APAGAR (CPA alto)",IF(AND(H8>0,N(I8)<=CPA_BE*(1+TOL)),"Prometedor / cerca del BE","Juntando datos")))))) | O8: =IF($A8="","",SUMIFS(Registro!$E$2:$E$1501,Registro!$C$2:$C$1501,$A8,Registro!$B$2:$B$1501,"Escala CBO")) | P8: =IF($A8="","",SUMIFS(Registro!$H$2:$H$1501,Registro!$C$2:$C$1501,$A8,Registro!$B$2:$B$1501,"Escala CBO")) | Q8: =IF(N(P8)>0,O8/P8,"") | R8: =IF(N(O8)>0,SUMIFS(Registro!$I$2:$I$1501,Registro!$C$2:$C$1501,$A8,Registro!$B$2:$B$1501,"Escala CBO")/O8,"") | S8: =IF(N(O8)>0,SUMIFS(Registro!$I$2:$I$1501,Registro!$C$2:$C$1501,$A8,Registro!$B$2:$B$1501,"Escala CBO")*(1-COM-COM_SHOP)-O8*(1+IMP_META),"") | T8: =IF(N(O8)=0,"",IF(P8=0,IF(O8>=K_SIN_VENTA*CPA_BE,"Sin ventas: revisar","Juntando datos"),IF(Q8<=CPA_BE,"Rentable","No rentable"))) | U8: =IF($A8="","",N(L8)+N(S8))
D9: =IF(COUNTIFS(Registro!$C$2:$C$1501,$A9)=0,"",_xlfn.MINIFS(Registro!$A$2:$A$1501,Registro!$C$2:$C$1501,$A9)) | E9: =IF($A9="","",COUNTIFS(Registro!$C$2:$C$1501,$A9,Registro!$E$2:$E$1501,">0")) | F9: =IF($A9="","",SUMIFS(Registro!$E$2:$E$1501,Registro!$C$2:$C$1501,$A9,Registro!$B$2:$B$1501,"Test ABO")) | G9: =IF($A9="","",F9/CPA_BE) | H9: =IF($A9="","",SUMIFS(Registro!$H$2:$H$1501,Registro!$C$2:$C$1501,$A9,Registro!$B$2:$B$1501,"Test ABO")) | I9: =IF(N(H9)>0,F9/H9,"") | J9: =IF(N(H9)>0,I9/CPA_BE-1,"") | K9: =IF(N(F9)>0,SUMIFS(Registro!$I$2:$I$1501,Registro!$C$2:$C$1501,$A9,Registro!$B$2:$B$1501,"Test ABO")/F9,"") | L9: =IF(N(F9)>0,SUMIFS(Registro!$I$2:$I$1501,Registro!$C$2:$C$1501,$A9,Registro!$B$2:$B$1501,"Test ABO")*(1-COM-COM_SHOP)-F9*(1+IMP_META),"") | M9: =IF(SUMIFS(Registro!$F$2:$F$1501,Registro!$C$2:$C$1501,$A9,Registro!$B$2:$B$1501,"Test ABO")>0,SUMIFS(Registro!$G$2:$G$1501,Registro!$C$2:$C$1501,$A9,Registro!$B$2:$B$1501,"Test ABO")/SUMIFS(Registro!$F$2:$F$1501,Registro!$C$2:$C$1501,$A9,Registro!$B$2:$B$1501,"Test ABO"),"") | N9: =IF($A9="","",IF(N(F9)=0,"Sin datos",IF(AND(H9>=MIN_VENTAS,N(I9)<=CPA_BE),"GANADOR → pasar a CBO",IF(AND(H9=0,F9>=K_SIN_VENTA*CPA_BE),"APAGAR (sin ventas)",IF(AND(H9>0,F9>=K_CARO*CPA_BE,N(I9)>CPA_BE*(1+TOL)),"APAGAR (CPA alto)",IF(AND(H9>0,N(I9)<=CPA_BE*(1+TOL)),"Prometedor / cerca del BE","Juntando datos")))))) | O9: =IF($A9="","",SUMIFS(Registro!$E$2:$E$1501,Registro!$C$2:$C$1501,$A9,Registro!$B$2:$B$1501,"Escala CBO")) | P9: =IF($A9="","",SUMIFS(Registro!$H$2:$H$1501,Registro!$C$2:$C$1501,$A9,Registro!$B$2:$B$1501,"Escala CBO")) | Q9: =IF(N(P9)>0,O9/P9,"") | R9: =IF(N(O9)>0,SUMIFS(Registro!$I$2:$I$1501,Registro!$C$2:$C$1501,$A9,Registro!$B$2:$B$1501,"Escala CBO")/O9,"") | S9: =IF(N(O9)>0,SUMIFS(Registro!$I$2:$I$1501,Registro!$C$2:$C$1501,$A9,Registro!$B$2:$B$1501,"Escala CBO")*(1-COM-COM_SHOP)-O9*(1+IMP_META),"") | T9: =IF(N(O9)=0,"",IF(P9=0,IF(O9>=K_SIN_VENTA*CPA_BE,"Sin ventas: revisar","Juntando datos"),IF(Q9<=CPA_BE,"Rentable","No rentable"))) | U9: =IF($A9="","",N(L9)+N(S9))
D10: =IF(COUNTIFS(Registro!$C$2:$C$1501,$A10)=0,"",_xlfn.MINIFS(Registro!$A$2:$A$1501,Registro!$C$2:$C$1501,$A10)) | E10: =IF($A10="","",COUNTIFS(Registro!$C$2:$C$1501,$A10,Registro!$E$2:$E$1501,">0")) | F10: =IF($A10="","",SUMIFS(Registro!$E$2:$E$1501,Registro!$C$2:$C$1501,$A10,Registro!$B$2:$B$1501,"Test ABO")) | G10: =IF($A10="","",F10/CPA_BE) | H10: =IF($A10="","",SUMIFS(Registro!$H$2:$H$1501,Registro!$C$2:$C$1501,$A10,Registro!$B$2:$B$1501,"Test ABO")) | I10: =IF(N(H10)>0,F10/H10,"") | J10: =IF(N(H10)>0,I10/CPA_BE-1,"") | K10: =IF(N(F10)>0,SUMIFS(Registro!$I$2:$I$1501,Registro!$C$2:$C$1501,$A10,Registro!$B$2:$B$1501,"Test ABO")/F10,"") | L10: =IF(N(F10)>0,SUMIFS(Registro!$I$2:$I$1501,Registro!$C$2:$C$1501,$A10,Registro!$B$2:$B$1501,"Test ABO")*(1-COM-COM_SHOP)-F10*(1+IMP_META),"") | M10: =IF(SUMIFS(Registro!$F$2:$F$1501,Registro!$C$2:$C$1501,$A10,Registro!$B$2:$B$1501,"Test ABO")>0,SUMIFS(Registro!$G$2:$G$1501,Registro!$C$2:$C$1501,$A10,Registro!$B$2:$B$1501,"Test ABO")/SUMIFS(Registro!$F$2:$F$1501,Registro!$C$2:$C$1501,$A10,Registro!$B$2:$B$1501,"Test ABO"),"") | N10: =IF($A10="","",IF(N(F10)=0,"Sin datos",IF(AND(H10>=MIN_VENTAS,N(I10)<=CPA_BE),"GANADOR → pasar a CBO",IF(AND(H10=0,F10>=K_SIN_VENTA*CPA_BE),"APAGAR (sin ventas)",IF(AND(H10>0,F10>=K_CARO*CPA_BE,N(I10)>CPA_BE*(1+TOL)),"APAGAR (CPA alto)",IF(AND(H10>0,N(I10)<=CPA_BE*(1+TOL)),"Prometedor / cerca del BE","Juntando datos")))))) | O10: =IF($A10="","",SUMIFS(Registro!$E$2:$E$1501,Registro!$C$2:$C$1501,$A10,Registro!$B$2:$B$1501,"Escala CBO")) | P10: =IF($A10="","",SUMIFS(Registro!$H$2:$H$1501,Registro!$C$2:$C$1501,$A10,Registro!$B$2:$B$1501,"Escala CBO")) | Q10: =IF(N(P10)>0,O10/P10,"") | R10: =IF(N(O10)>0,SUMIFS(Registro!$I$2:$I$1501,Registro!$C$2:$C$1501,$A10,Registro!$B$2:$B$1501,"Escala CBO")/O10,"") | S10: =IF(N(O10)>0,SUMIFS(Registro!$I$2:$I$1501,Registro!$C$2:$C$1501,$A10,Registro!$B$2:$B$1501,"Escala CBO")*(1-COM-COM_SHOP)-O10*(1+IMP_META),"") | T10: =IF(N(O10)=0,"",IF(P10=0,IF(O10>=K_SIN_VENTA*CPA_BE,"Sin ventas: revisar","Juntando datos"),IF(Q10<=CPA_BE,"Rentable","No rentable"))) | U10: =IF($A10="","",N(L10)+N(S10))
D11: =IF(COUNTIFS(Registro!$C$2:$C$1501,$A11)=0,"",_xlfn.MINIFS(Registro!$A$2:$A$1501,Registro!$C$2:$C$1501,$A11)) | E11: =IF($A11="","",COUNTIFS(Registro!$C$2:$C$1501,$A11,Registro!$E$2:$E$1501,">0")) | F11: =IF($A11="","",SUMIFS(Registro!$E$2:$E$1501,Registro!$C$2:$C$1501,$A11,Registro!$B$2:$B$1501,"Test ABO")) | G11: =IF($A11="","",F11/CPA_BE) | H11: =IF($A11="","",SUMIFS(Registro!$H$2:$H$1501,Registro!$C$2:$C$1501,$A11,Registro!$B$2:$B$1501,"Test ABO")) | I11: =IF(N(H11)>0,F11/H11,"") | J11: =IF(N(H11)>0,I11/CPA_BE-1,"") | K11: =IF(N(F11)>0,SUMIFS(Registro!$I$2:$I$1501,Registro!$C$2:$C$1501,$A11,Registro!$B$2:$B$1501,"Test ABO")/F11,"") | L11: =IF(N(F11)>0,SUMIFS(Registro!$I$2:$I$1501,Registro!$C$2:$C$1501,$A11,Registro!$B$2:$B$1501,"Test ABO")*(1-COM-COM_SHOP)-F11*(1+IMP_META),"") | M11: =IF(SUMIFS(Registro!$F$2:$F$1501,Registro!$C$2:$C$1501,$A11,Registro!$B$2:$B$1501,"Test ABO")>0,SUMIFS(Registro!$G$2:$G$1501,Registro!$C$2:$C$1501,$A11,Registro!$B$2:$B$1501,"Test ABO")/SUMIFS(Registro!$F$2:$F$1501,Registro!$C$2:$C$1501,$A11,Registro!$B$2:$B$1501,"Test ABO"),"") | N11: =IF($A11="","",IF(N(F11)=0,"Sin datos",IF(AND(H11>=MIN_VENTAS,N(I11)<=CPA_BE),"GANADOR → pasar a CBO",IF(AND(H11=0,F11>=K_SIN_VENTA*CPA_BE),"APAGAR (sin ventas)",IF(AND(H11>0,F11>=K_CARO*CPA_BE,N(I11)>CPA_BE*(1+TOL)),"APAGAR (CPA alto)",IF(AND(H11>0,N(I11)<=CPA_BE*(1+TOL)),"Prometedor / cerca del BE","Juntando datos")))))) | O11: =IF($A11="","",SUMIFS(Registro!$E$2:$E$1501,Registro!$C$2:$C$1501,$A11,Registro!$B$2:$B$1501,"Escala CBO")) | P11: =IF($A11="","",SUMIFS(Registro!$H$2:$H$1501,Registro!$C$2:$C$1501,$A11,Registro!$B$2:$B$1501,"Escala CBO")) | Q11: =IF(N(P11)>0,O11/P11,"") | R11: =IF(N(O11)>0,SUMIFS(Registro!$I$2:$I$1501,Registro!$C$2:$C$1501,$A11,Registro!$B$2:$B$1501,"Escala CBO")/O11,"") | S11: =IF(N(O11)>0,SUMIFS(Registro!$I$2:$I$1501,Registro!$C$2:$C$1501,$A11,Registro!$B$2:$B$1501,"Escala CBO")*(1-COM-COM_SHOP)-O11*(1+IMP_META),"") | T11: =IF(N(O11)=0,"",IF(P11=0,IF(O11>=K_SIN_VENTA*CPA_BE,"Sin ventas: revisar","Juntando datos"),IF(Q11<=CPA_BE,"Rentable","No rentable"))) | U11: =IF($A11="","",N(L11)+N(S11))
D12: =IF(COUNTIFS(Registro!$C$2:$C$1501,$A12)=0,"",_xlfn.MINIFS(Registro!$A$2:$A$1501,Registro!$C$2:$C$1501,$A12)) | E12: =IF($A12="","",COUNTIFS(Registro!$C$2:$C$1501,$A12,Registro!$E$2:$E$1501,">0")) | F12: =IF($A12="","",SUMIFS(Registro!$E$2:$E$1501,Registro!$C$2:$C$1501,$A12,Registro!$B$2:$B$1501,"Test ABO")) | G12: =IF($A12="","",F12/CPA_BE) | H12: =IF($A12="","",SUMIFS(Registro!$H$2:$H$1501,Registro!$C$2:$C$1501,$A12,Registro!$B$2:$B$1501,"Test ABO")) | I12: =IF(N(H12)>0,F12/H12,"") | J12: =IF(N(H12)>0,I12/CPA_BE-1,"") | K12: =IF(N(F12)>0,SUMIFS(Registro!$I$2:$I$1501,Registro!$C$2:$C$1501,$A12,Registro!$B$2:$B$1501,"Test ABO")/F12,"") | L12: =IF(N(F12)>0,SUMIFS(Registro!$I$2:$I$1501,Registro!$C$2:$C$1501,$A12,Registro!$B$2:$B$1501,"Test ABO")*(1-COM-COM_SHOP)-F12*(1+IMP_META),"") | M12: =IF(SUMIFS(Registro!$F$2:$F$1501,Registro!$C$2:$C$1501,$A12,Registro!$B$2:$B$1501,"Test ABO")>0,SUMIFS(Registro!$G$2:$G$1501,Registro!$C$2:$C$1501,$A12,Registro!$B$2:$B$1501,"Test ABO")/SUMIFS(Registro!$F$2:$F$1501,Registro!$C$2:$C$1501,$A12,Registro!$B$2:$B$1501,"Test ABO"),"") | N12: =IF($A12="","",IF(N(F12)=0,"Sin datos",IF(AND(H12>=MIN_VENTAS,N(I12)<=CPA_BE),"GANADOR → pasar a CBO",IF(AND(H12=0,F12>=K_SIN_VENTA*CPA_BE),"APAGAR (sin ventas)",IF(AND(H12>0,F12>=K_CARO*CPA_BE,N(I12)>CPA_BE*(1+TOL)),"APAGAR (CPA alto)",IF(AND(H12>0,N(I12)<=CPA_BE*(1+TOL)),"Prometedor / cerca del BE","Juntando datos")))))) | O12: =IF($A12="","",SUMIFS(Registro!$E$2:$E$1501,Registro!$C$2:$C$1501,$A12,Registro!$B$2:$B$1501,"Escala CBO")) | P12: =IF($A12="","",SUMIFS(Registro!$H$2:$H$1501,Registro!$C$2:$C$1501,$A12,Registro!$B$2:$B$1501,"Escala CBO")) | Q12: =IF(N(P12)>0,O12/P12,"") | R12: =IF(N(O12)>0,SUMIFS(Registro!$I$2:$I$1501,Registro!$C$2:$C$1501,$A12,Registro!$B$2:$B$1501,"Escala CBO")/O12,"") | S12: =IF(N(O12)>0,SUMIFS(Registro!$I$2:$I$1501,Registro!$C$2:$C$1501,$A12,Registro!$B$2:$B$1501,"Escala CBO")*(1-COM-COM_SHOP)-O12*(1+IMP_META),"") | T12: =IF(N(O12)=0,"",IF(P12=0,IF(O12>=K_SIN_VENTA*CPA_BE,"Sin ventas: revisar","Juntando datos"),IF(Q12<=CPA_BE,"Rentable","No rentable"))) | U12: =IF($A12="","",N(L12)+N(S12))
D13: =IF(COUNTIFS(Registro!$C$2:$C$1501,$A13)=0,"",_xlfn.MINIFS(Registro!$A$2:$A$1501,Registro!$C$2:$C$1501,$A13)) | E13: =IF($A13="","",COUNTIFS(Registro!$C$2:$C$1501,$A13,Registro!$E$2:$E$1501,">0")) | F13: =IF($A13="","",SUMIFS(Registro!$E$2:$E$1501,Registro!$C$2:$C$1501,$A13,Registro!$B$2:$B$1501,"Test ABO")) | G13: =IF($A13="","",F13/CPA_BE) | H13: =IF($A13="","",SUMIFS(Registro!$H$2:$H$1501,Registro!$C$2:$C$1501,$A13,Registro!$B$2:$B$1501,"Test ABO")) | I13: =IF(N(H13)>0,F13/H13,"") | J13: =IF(N(H13)>0,I13/CPA_BE-1,"") | K13: =IF(N(F13)>0,SUMIFS(Registro!$I$2:$I$1501,Registro!$C$2:$C$1501,$A13,Registro!$B$2:$B$1501,"Test ABO")/F13,"") | L13: =IF(N(F13)>0,SUMIFS(Registro!$I$2:$I$1501,Registro!$C$2:$C$1501,$A13,Registro!$B$2:$B$1501,"Test ABO")*(1-COM-COM_SHOP)-F13*(1+IMP_META),"") | M13: =IF(SUMIFS(Registro!$F$2:$F$1501,Registro!$C$2:$C$1501,$A13,Registro!$B$2:$B$1501,"Test ABO")>0,SUMIFS(Registro!$G$2:$G$1501,Registro!$C$2:$C$1501,$A13,Registro!$B$2:$B$1501,"Test ABO")/SUMIFS(Registro!$F$2:$F$1501,Registro!$C$2:$C$1501,$A13,Registro!$B$2:$B$1501,"Test ABO"),"") | N13: =IF($A13="","",IF(N(F13)=0,"Sin datos",IF(AND(H13>=MIN_VENTAS,N(I13)<=CPA_BE),"GANADOR → pasar a CBO",IF(AND(H13=0,F13>=K_SIN_VENTA*CPA_BE),"APAGAR (sin ventas)",IF(AND(H13>0,F13>=K_CARO*CPA_BE,N(I13)>CPA_BE*(1+TOL)),"APAGAR (CPA alto)",IF(AND(H13>0,N(I13)<=CPA_BE*(1+TOL)),"Prometedor / cerca del BE","Juntando datos")))))) | O13: =IF($A13="","",SUMIFS(Registro!$E$2:$E$1501,Registro!$C$2:$C$1501,$A13,Registro!$B$2:$B$1501,"Escala CBO")) | P13: =IF($A13="","",SUMIFS(Registro!$H$2:$H$1501,Registro!$C$2:$C$1501,$A13,Registro!$B$2:$B$1501,"Escala CBO")) | Q13: =IF(N(P13)>0,O13/P13,"") | R13: =IF(N(O13)>0,SUMIFS(Registro!$I$2:$I$1501,Registro!$C$2:$C$1501,$A13,Registro!$B$2:$B$1501,"Escala CBO")/O13,"") | S13: =IF(N(O13)>0,SUMIFS(Registro!$I$2:$I$1501,Registro!$C$2:$C$1501,$A13,Registro!$B$2:$B$1501,"Escala CBO")*(1-COM-COM_SHOP)-O13*(1+IMP_META),"") | T13: =IF(N(O13)=0,"",IF(P13=0,IF(O13>=K_SIN_VENTA*CPA_BE,"Sin ventas: revisar","Juntando datos"),IF(Q13<=CPA_BE,"Rentable","No rentable"))) | U13: =IF($A13="","",N(L13)+N(S13))
D14: =IF(COUNTIFS(Registro!$C$2:$C$1501,$A14)=0,"",_xlfn.MINIFS(Registro!$A$2:$A$1501,Registro!$C$2:$C$1501,$A14)) | E14: =IF($A14="","",COUNTIFS(Registro!$C$2:$C$1501,$A14,Registro!$E$2:$E$1501,">0")) | F14: =IF($A14="","",SUMIFS(Registro!$E$2:$E$1501,Registro!$C$2:$C$1501,$A14,Registro!$B$2:$B$1501,"Test ABO")) | G14: =IF($A14="","",F14/CPA_BE) | H14: =IF($A14="","",SUMIFS(Registro!$H$2:$H$1501,Registro!$C$2:$C$1501,$A14,Registro!$B$2:$B$1501,"Test ABO")) | I14: =IF(N(H14)>0,F14/H14,"") | J14: =IF(N(H14)>0,I14/CPA_BE-1,"") | K14: =IF(N(F14)>0,SUMIFS(Registro!$I$2:$I$1501,Registro!$C$2:$C$1501,$A14,Registro!$B$2:$B$1501,"Test ABO")/F14,"") | L14: =IF(N(F14)>0,SUMIFS(Registro!$I$2:$I$1501,Registro!$C$2:$C$1501,$A14,Registro!$B$2:$B$1501,"Test ABO")*(1-COM-COM_SHOP)-F14*(1+IMP_META),"") | M14: =IF(SUMIFS(Registro!$F$2:$F$1501,Registro!$C$2:$C$1501,$A14,Registro!$B$2:$B$1501,"Test ABO")>0,SUMIFS(Registro!$G$2:$G$1501,Registro!$C$2:$C$1501,$A14,Registro!$B$2:$B$1501,"Test ABO")/SUMIFS(Registro!$F$2:$F$1501,Registro!$C$2:$C$1501,$A14,Registro!$B$2:$B$1501,"Test ABO"),"") | N14: =IF($A14="","",IF(N(F14)=0,"Sin datos",IF(AND(H14>=MIN_VENTAS,N(I14)<=CPA_BE),"GANADOR → pasar a CBO",IF(AND(H14=0,F14>=K_SIN_VENTA*CPA_BE),"APAGAR (sin ventas)",IF(AND(H14>0,F14>=K_CARO*CPA_BE,N(I14)>CPA_BE*(1+TOL)),"APAGAR (CPA alto)",IF(AND(H14>0,N(I14)<=CPA_BE*(1+TOL)),"Prometedor / cerca del BE","Juntando datos")))))) | O14: =IF($A14="","",SUMIFS(Registro!$E$2:$E$1501,Registro!$C$2:$C$1501,$A14,Registro!$B$2:$B$1501,"Escala CBO")) | P14: =IF($A14="","",SUMIFS(Registro!$H$2:$H$1501,Registro!$C$2:$C$1501,$A14,Registro!$B$2:$B$1501,"Escala CBO")) | Q14: =IF(N(P14)>0,O14/P14,"") | R14: =IF(N(O14)>0,SUMIFS(Registro!$I$2:$I$1501,Registro!$C$2:$C$1501,$A14,Registro!$B$2:$B$1501,"Escala CBO")/O14,"") | S14: =IF(N(O14)>0,SUMIFS(Registro!$I$2:$I$1501,Registro!$C$2:$C$1501,$A14,Registro!$B$2:$B$1501,"Escala CBO")*(1-COM-COM_SHOP)-O14*(1+IMP_META),"") | T14: =IF(N(O14)=0,"",IF(P14=0,IF(O14>=K_SIN_VENTA*CPA_BE,"Sin ventas: revisar","Juntando datos"),IF(Q14<=CPA_BE,"Rentable","No rentable"))) | U14: =IF($A14="","",N(L14)+N(S14))
D15: =IF(COUNTIFS(Registro!$C$2:$C$1501,$A15)=0,"",_xlfn.MINIFS(Registro!$A$2:$A$1501,Registro!$C$2:$C$1501,$A15)) | E15: =IF($A15="","",COUNTIFS(Registro!$C$2:$C$1501,$A15,Registro!$E$2:$E$1501,">0")) | F15: =IF($A15="","",SUMIFS(Registro!$E$2:$E$1501,Registro!$C$2:$C$1501,$A15,Registro!$B$2:$B$1501,"Test ABO")) | G15: =IF($A15="","",F15/CPA_BE) | H15: =IF($A15="","",SUMIFS(Registro!$H$2:$H$1501,Registro!$C$2:$C$1501,$A15,Registro!$B$2:$B$1501,"Test ABO")) | I15: =IF(N(H15)>0,F15/H15,"") | J15: =IF(N(H15)>0,I15/CPA_BE-1,"") | K15: =IF(N(F15)>0,SUMIFS(Registro!$I$2:$I$1501,Registro!$C$2:$C$1501,$A15,Registro!$B$2:$B$1501,"Test ABO")/F15,"") | L15: =IF(N(F15)>0,SUMIFS(Registro!$I$2:$I$1501,Registro!$C$2:$C$1501,$A15,Registro!$B$2:$B$1501,"Test ABO")*(1-COM-COM_SHOP)-F15*(1+IMP_META),"") | M15: =IF(SUMIFS(Registro!$F$2:$F$1501,Registro!$C$2:$C$1501,$A15,Registro!$B$2:$B$1501,"Test ABO")>0,SUMIFS(Registro!$G$2:$G$1501,Registro!$C$2:$C$1501,$A15,Registro!$B$2:$B$1501,"Test ABO")/SUMIFS(Registro!$F$2:$F$1501,Registro!$C$2:$C$1501,$A15,Registro!$B$2:$B$1501,"Test ABO"),"") | N15: =IF($A15="","",IF(N(F15)=0,"Sin datos",IF(AND(H15>=MIN_VENTAS,N(I15)<=CPA_BE),"GANADOR → pasar a CBO",IF(AND(H15=0,F15>=K_SIN_VENTA*CPA_BE),"APAGAR (sin ventas)",IF(AND(H15>0,F15>=K_CARO*CPA_BE,N(I15)>CPA_BE*(1+TOL)),"APAGAR (CPA alto)",IF(AND(H15>0,N(I15)<=CPA_BE*(1+TOL)),"Prometedor / cerca del BE","Juntando datos")))))) | O15: =IF($A15="","",SUMIFS(Registro!$E$2:$E$1501,Registro!$C$2:$C$1501,$A15,Registro!$B$2:$B$1501,"Escala CBO")) | P15: =IF($A15="","",SUMIFS(Registro!$H$2:$H$1501,Registro!$C$2:$C$1501,$A15,Registro!$B$2:$B$1501,"Escala CBO")) | Q15: =IF(N(P15)>0,O15/P15,"") | R15: =IF(N(O15)>0,SUMIFS(Registro!$I$2:$I$1501,Registro!$C$2:$C$1501,$A15,Registro!$B$2:$B$1501,"Escala CBO")/O15,"") | S15: =IF(N(O15)>0,SUMIFS(Registro!$I$2:$I$1501,Registro!$C$2:$C$1501,$A15,Registro!$B$2:$B$1501,"Escala CBO")*(1-COM-COM_SHOP)-O15*(1+IMP_META),"") | T15: =IF(N(O15)=0,"",IF(P15=0,IF(O15>=K_SIN_VENTA*CPA_BE,"Sin ventas: revisar","Juntando datos"),IF(Q15<=CPA_BE,"Rentable","No rentable"))) | U15: =IF($A15="","",N(L15)+N(S15))
D16: =IF(COUNTIFS(Registro!$C$2:$C$1501,$A16)=0,"",_xlfn.MINIFS(Registro!$A$2:$A$1501,Registro!$C$2:$C$1501,$A16)) | E16: =IF($A16="","",COUNTIFS(Registro!$C$2:$C$1501,$A16,Registro!$E$2:$E$1501,">0")) | F16: =IF($A16="","",SUMIFS(Registro!$E$2:$E$1501,Registro!$C$2:$C$1501,$A16,Registro!$B$2:$B$1501,"Test ABO")) | G16: =IF($A16="","",F16/CPA_BE) | H16: =IF($A16="","",SUMIFS(Registro!$H$2:$H$1501,Registro!$C$2:$C$1501,$A16,Registro!$B$2:$B$1501,"Test ABO")) | I16: =IF(N(H16)>0,F16/H16,"") | J16: =IF(N(H16)>0,I16/CPA_BE-1,"") | K16: =IF(N(F16)>0,SUMIFS(Registro!$I$2:$I$1501,Registro!$C$2:$C$1501,$A16,Registro!$B$2:$B$1501,"Test ABO")/F16,"") | L16: =IF(N(F16)>0,SUMIFS(Registro!$I$2:$I$1501,Registro!$C$2:$C$1501,$A16,Registro!$B$2:$B$1501,"Test ABO")*(1-COM-COM_SHOP)-F16*(1+IMP_META),"") | M16: =IF(SUMIFS(Registro!$F$2:$F$1501,Registro!$C$2:$C$1501,$A16,Registro!$B$2:$B$1501,"Test ABO")>0,SUMIFS(Registro!$G$2:$G$1501,Registro!$C$2:$C$1501,$A16,Registro!$B$2:$B$1501,"Test ABO")/SUMIFS(Registro!$F$2:$F$1501,Registro!$C$2:$C$1501,$A16,Registro!$B$2:$B$1501,"Test ABO"),"") | N16: =IF($A16="","",IF(N(F16)=0,"Sin datos",IF(AND(H16>=MIN_VENTAS,N(I16)<=CPA_BE),"GANADOR → pasar a CBO",IF(AND(H16=0,F16>=K_SIN_VENTA*CPA_BE),"APAGAR (sin ventas)",IF(AND(H16>0,F16>=K_CARO*CPA_BE,N(I16)>CPA_BE*(1+TOL)),"APAGAR (CPA alto)",IF(AND(H16>0,N(I16)<=CPA_BE*(1+TOL)),"Prometedor / cerca del BE","Juntando datos")))))) | O16: =IF($A16="","",SUMIFS(Registro!$E$2:$E$1501,Registro!$C$2:$C$1501,$A16,Registro!$B$2:$B$1501,"Escala CBO")) | P16: =IF($A16="","",SUMIFS(Registro!$H$2:$H$1501,Registro!$C$2:$C$1501,$A16,Registro!$B$2:$B$1501,"Escala CBO")) | Q16: =IF(N(P16)>0,O16/P16,"") | R16: =IF(N(O16)>0,SUMIFS(Registro!$I$2:$I$1501,Registro!$C$2:$C$1501,$A16,Registro!$B$2:$B$1501,"Escala CBO")/O16,"") | S16: =IF(N(O16)>0,SUMIFS(Registro!$I$2:$I$1501,Registro!$C$2:$C$1501,$A16,Registro!$B$2:$B$1501,"Escala CBO")*(1-COM-COM_SHOP)-O16*(1+IMP_META),"") | T16: =IF(N(O16)=0,"",IF(P16=0,IF(O16>=K_SIN_VENTA*CPA_BE,"Sin ventas: revisar","Juntando datos"),IF(Q16<=CPA_BE,"Rentable","No rentable"))) | U16: =IF($A16="","",N(L16)+N(S16))
D17: =IF(COUNTIFS(Registro!$C$2:$C$1501,$A17)=0,"",_xlfn.MINIFS(Registro!$A$2:$A$1501,Registro!$C$2:$C$1501,$A17)) | E17: =IF($A17="","",COUNTIFS(Registro!$C$2:$C$1501,$A17,Registro!$E$2:$E$1501,">0")) | F17: =IF($A17="","",SUMIFS(Registro!$E$2:$E$1501,Registro!$C$2:$C$1501,$A17,Registro!$B$2:$B$1501,"Test ABO")) | G17: =IF($A17="","",F17/CPA_BE) | H17: =IF($A17="","",SUMIFS(Registro!$H$2:$H$1501,Registro!$C$2:$C$1501,$A17,Registro!$B$2:$B$1501,"Test ABO")) | I17: =IF(N(H17)>0,F17/H17,"") | J17: =IF(N(H17)>0,I17/CPA_BE-1,"") | K17: =IF(N(F17)>0,SUMIFS(Registro!$I$2:$I$1501,Registro!$C$2:$C$1501,$A17,Registro!$B$2:$B$1501,"Test ABO")/F17,"") | L17: =IF(N(F17)>0,SUMIFS(Registro!$I$2:$I$1501,Registro!$C$2:$C$1501,$A17,Registro!$B$2:$B$1501,"Test ABO")*(1-COM-COM_SHOP)-F17*(1+IMP_META),"") | M17: =IF(SUMIFS(Registro!$F$2:$F$1501,Registro!$C$2:$C$1501,$A17,Registro!$B$2:$B$1501,"Test ABO")>0,SUMIFS(Registro!$G$2:$G$1501,Registro!$C$2:$C$1501,$A17,Registro!$B$2:$B$1501,"Test ABO")/SUMIFS(Registro!$F$2:$F$1501,Registro!$C$2:$C$1501,$A17,Registro!$B$2:$B$1501,"Test ABO"),"") | N17: =IF($A17="","",IF(N(F17)=0,"Sin datos",IF(AND(H17>=MIN_VENTAS,N(I17)<=CPA_BE),"GANADOR → pasar a CBO",IF(AND(H17=0,F17>=K_SIN_VENTA*CPA_BE),"APAGAR (sin ventas)",IF(AND(H17>0,F17>=K_CARO*CPA_BE,N(I17)>CPA_BE*(1+TOL)),"APAGAR (CPA alto)",IF(AND(H17>0,N(I17)<=CPA_BE*(1+TOL)),"Prometedor / cerca del BE","Juntando datos")))))) | O17: =IF($A17="","",SUMIFS(Registro!$E$2:$E$1501,Registro!$C$2:$C$1501,$A17,Registro!$B$2:$B$1501,"Escala CBO")) | P17: =IF($A17="","",SUMIFS(Registro!$H$2:$H$1501,Registro!$C$2:$C$1501,$A17,Registro!$B$2:$B$1501,"Escala CBO")) | Q17: =IF(N(P17)>0,O17/P17,"") | R17: =IF(N(O17)>0,SUMIFS(Registro!$I$2:$I$1501,Registro!$C$2:$C$1501,$A17,Registro!$B$2:$B$1501,"Escala CBO")/O17,"") | S17: =IF(N(O17)>0,SUMIFS(Registro!$I$2:$I$1501,Registro!$C$2:$C$1501,$A17,Registro!$B$2:$B$1501,"Escala CBO")*(1-COM-COM_SHOP)-O17*(1+IMP_META),"") | T17: =IF(N(O17)=0,"",IF(P17=0,IF(O17>=K_SIN_VENTA*CPA_BE,"Sin ventas: revisar","Juntando datos"),IF(Q17<=CPA_BE,"Rentable","No rentable"))) | U17: =IF($A17="","",N(L17)+N(S17))
D18: =IF(COUNTIFS(Registro!$C$2:$C$1501,$A18)=0,"",_xlfn.MINIFS(Registro!$A$2:$A$1501,Registro!$C$2:$C$1501,$A18)) | E18: =IF($A18="","",COUNTIFS(Registro!$C$2:$C$1501,$A18,Registro!$E$2:$E$1501,">0")) | F18: =IF($A18="","",SUMIFS(Registro!$E$2:$E$1501,Registro!$C$2:$C$1501,$A18,Registro!$B$2:$B$1501,"Test ABO")) | G18: =IF($A18="","",F18/CPA_BE) | H18: =IF($A18="","",SUMIFS(Registro!$H$2:$H$1501,Registro!$C$2:$C$1501,$A18,Registro!$B$2:$B$1501,"Test ABO")) | I18: =IF(N(H18)>0,F18/H18,"") | J18: =IF(N(H18)>0,I18/CPA_BE-1,"") | K18: =IF(N(F18)>0,SUMIFS(Registro!$I$2:$I$1501,Registro!$C$2:$C$1501,$A18,Registro!$B$2:$B$1501,"Test ABO")/F18,"") | L18: =IF(N(F18)>0,SUMIFS(Registro!$I$2:$I$1501,Registro!$C$2:$C$1501,$A18,Registro!$B$2:$B$1501,"Test ABO")*(1-COM-COM_SHOP)-F18*(1+IMP_META),"") | M18: =IF(SUMIFS(Registro!$F$2:$F$1501,Registro!$C$2:$C$1501,$A18,Registro!$B$2:$B$1501,"Test ABO")>0,SUMIFS(Registro!$G$2:$G$1501,Registro!$C$2:$C$1501,$A18,Registro!$B$2:$B$1501,"Test ABO")/SUMIFS(Registro!$F$2:$F$1501,Registro!$C$2:$C$1501,$A18,Registro!$B$2:$B$1501,"Test ABO"),"") | N18: =IF($A18="","",IF(N(F18)=0,"Sin datos",IF(AND(H18>=MIN_VENTAS,N(I18)<=CPA_BE),"GANADOR → pasar a CBO",IF(AND(H18=0,F18>=K_SIN_VENTA*CPA_BE),"APAGAR (sin ventas)",IF(AND(H18>0,F18>=K_CARO*CPA_BE,N(I18)>CPA_BE*(1+TOL)),"APAGAR (CPA alto)",IF(AND(H18>0,N(I18)<=CPA_BE*(1+TOL)),"Prometedor / cerca del BE","Juntando datos")))))) | O18: =IF($A18="","",SUMIFS(Registro!$E$2:$E$1501,Registro!$C$2:$C$1501,$A18,Registro!$B$2:$B$1501,"Escala CBO")) | P18: =IF($A18="","",SUMIFS(Registro!$H$2:$H$1501,Registro!$C$2:$C$1501,$A18,Registro!$B$2:$B$1501,"Escala CBO")) | Q18: =IF(N(P18)>0,O18/P18,"") | R18: =IF(N(O18)>0,SUMIFS(Registro!$I$2:$I$1501,Registro!$C$2:$C$1501,$A18,Registro!$B$2:$B$1501,"Escala CBO")/O18,"") | S18: =IF(N(O18)>0,SUMIFS(Registro!$I$2:$I$1501,Registro!$C$2:$C$1501,$A18,Registro!$B$2:$B$1501,"Escala CBO")*(1-COM-COM_SHOP)-O18*(1+IMP_META),"") | T18: =IF(N(O18)=0,"",IF(P18=0,IF(O18>=K_SIN_VENTA*CPA_BE,"Sin ventas: revisar","Juntando datos"),IF(Q18<=CPA_BE,"Rentable","No rentable"))) | U18: =IF($A18="","",N(L18)+N(S18))
D19: =IF(COUNTIFS(Registro!$C$2:$C$1501,$A19)=0,"",_xlfn.MINIFS(Registro!$A$2:$A$1501,Registro!$C$2:$C$1501,$A19)) | E19: =IF($A19="","",COUNTIFS(Registro!$C$2:$C$1501,$A19,Registro!$E$2:$E$1501,">0")) | F19: =IF($A19="","",SUMIFS(Registro!$E$2:$E$1501,Registro!$C$2:$C$1501,$A19,Registro!$B$2:$B$1501,"Test ABO")) | G19: =IF($A19="","",F19/CPA_BE) | H19: =IF($A19="","",SUMIFS(Registro!$H$2:$H$1501,Registro!$C$2:$C$1501,$A19,Registro!$B$2:$B$1501,"Test ABO")) | I19: =IF(N(H19)>0,F19/H19,"") | J19: =IF(N(H19)>0,I19/CPA_BE-1,"") | K19: =IF(N(F19)>0,SUMIFS(Registro!$I$2:$I$1501,Registro!$C$2:$C$1501,$A19,Registro!$B$2:$B$1501,"Test ABO")/F19,"") | L19: =IF(N(F19)>0,SUMIFS(Registro!$I$2:$I$1501,Registro!$C$2:$C$1501,$A19,Registro!$B$2:$B$1501,"Test ABO")*(1-COM-COM_SHOP)-F19*(1+IMP_META),"") | M19: =IF(SUMIFS(Registro!$F$2:$F$1501,Registro!$C$2:$C$1501,$A19,Registro!$B$2:$B$1501,"Test ABO")>0,SUMIFS(Registro!$G$2:$G$1501,Registro!$C$2:$C$1501,$A19,Registro!$B$2:$B$1501,"Test ABO")/SUMIFS(Registro!$F$2:$F$1501,Registro!$C$2:$C$1501,$A19,Registro!$B$2:$B$1501,"Test ABO"),"") | N19: =IF($A19="","",IF(N(F19)=0,"Sin datos",IF(AND(H19>=MIN_VENTAS,N(I19)<=CPA_BE),"GANADOR → pasar a CBO",IF(AND(H19=0,F19>=K_SIN_VENTA*CPA_BE),"APAGAR (sin ventas)",IF(AND(H19>0,F19>=K_CARO*CPA_BE,N(I19)>CPA_BE*(1+TOL)),"APAGAR (CPA alto)",IF(AND(H19>0,N(I19)<=CPA_BE*(1+TOL)),"Prometedor / cerca del BE","Juntando datos")))))) | O19: =IF($A19="","",SUMIFS(Registro!$E$2:$E$1501,Registro!$C$2:$C$1501,$A19,Registro!$B$2:$B$1501,"Escala CBO")) | P19: =IF($A19="","",SUMIFS(Registro!$H$2:$H$1501,Registro!$C$2:$C$1501,$A19,Registro!$B$2:$B$1501,"Escala CBO")) | Q19: =IF(N(P19)>0,O19/P19,"") | R19: =IF(N(O19)>0,SUMIFS(Registro!$I$2:$I$1501,Registro!$C$2:$C$1501,$A19,Registro!$B$2:$B$1501,"Escala CBO")/O19,"") | S19: =IF(N(O19)>0,SUMIFS(Registro!$I$2:$I$1501,Registro!$C$2:$C$1501,$A19,Registro!$B$2:$B$1501,"Escala CBO")*(1-COM-COM_SHOP)-O19*(1+IMP_META),"") | T19: =IF(N(O19)=0,"",IF(P19=0,IF(O19>=K_SIN_VENTA*CPA_BE,"Sin ventas: revisar","Juntando datos"),IF(Q19<=CPA_BE,"Rentable","No rentable"))) | U19: =IF($A19="","",N(L19)+N(S19))
D20: =IF(COUNTIFS(Registro!$C$2:$C$1501,$A20)=0,"",_xlfn.MINIFS(Registro!$A$2:$A$1501,Registro!$C$2:$C$1501,$A20)) | E20: =IF($A20="","",COUNTIFS(Registro!$C$2:$C$1501,$A20,Registro!$E$2:$E$1501,">0")) | F20: =IF($A20="","",SUMIFS(Registro!$E$2:$E$1501,Registro!$C$2:$C$1501,$A20,Registro!$B$2:$B$1501,"Test ABO")) | G20: =IF($A20="","",F20/CPA_BE) | H20: =IF($A20="","",SUMIFS(Registro!$H$2:$H$1501,Registro!$C$2:$C$1501,$A20,Registro!$B$2:$B$1501,"Test ABO")) | I20: =IF(N(H20)>0,F20/H20,"") | J20: =IF(N(H20)>0,I20/CPA_BE-1,"") | K20: =IF(N(F20)>0,SUMIFS(Registro!$I$2:$I$1501,Registro!$C$2:$C$1501,$A20,Registro!$B$2:$B$1501,"Test ABO")/F20,"") | L20: =IF(N(F20)>0,SUMIFS(Registro!$I$2:$I$1501,Registro!$C$2:$C$1501,$A20,Registro!$B$2:$B$1501,"Test ABO")*(1-COM-COM_SHOP)-F20*(1+IMP_META),"") | M20: =IF(SUMIFS(Registro!$F$2:$F$1501,Registro!$C$2:$C$1501,$A20,Registro!$B$2:$B$1501,"Test ABO")>0,SUMIFS(Registro!$G$2:$G$1501,Registro!$C$2:$C$1501,$A20,Registro!$B$2:$B$1501,"Test ABO")/SUMIFS(Registro!$F$2:$F$1501,Registro!$C$2:$C$1501,$A20,Registro!$B$2:$B$1501,"Test ABO"),"") | N20: =IF($A20="","",IF(N(F20)=0,"Sin datos",IF(AND(H20>=MIN_VENTAS,N(I20)<=CPA_BE),"GANADOR → pasar a CBO",IF(AND(H20=0,F20>=K_SIN_VENTA*CPA_BE),"APAGAR (sin ventas)",IF(AND(H20>0,F20>=K_CARO*CPA_BE,N(I20)>CPA_BE*(1+TOL)),"APAGAR (CPA alto)",IF(AND(H20>0,N(I20)<=CPA_BE*(1+TOL)),"Prometedor / cerca del BE","Juntando datos")))))) | O20: =IF($A20="","",SUMIFS(Registro!$E$2:$E$1501,Registro!$C$2:$C$1501,$A20,Registro!$B$2:$B$1501,"Escala CBO")) | P20: =IF($A20="","",SUMIFS(Registro!$H$2:$H$1501,Registro!$C$2:$C$1501,$A20,Registro!$B$2:$B$1501,"Escala CBO")) | Q20: =IF(N(P20)>0,O20/P20,"") | R20: =IF(N(O20)>0,SUMIFS(Registro!$I$2:$I$1501,Registro!$C$2:$C$1501,$A20,Registro!$B$2:$B$1501,"Escala CBO")/O20,"") | S20: =IF(N(O20)>0,SUMIFS(Registro!$I$2:$I$1501,Registro!$C$2:$C$1501,$A20,Registro!$B$2:$B$1501,"Escala CBO")*(1-COM-COM_SHOP)-O20*(1+IMP_META),"") | T20: =IF(N(O20)=0,"",IF(P20=0,IF(O20>=K_SIN_VENTA*CPA_BE,"Sin ventas: revisar","Juntando datos"),IF(Q20<=CPA_BE,"Rentable","No rentable"))) | U20: =IF($A20="","",N(L20)+N(S20))
... D65: =IF(COUNTIFS(Registro!$C$2:$C$1501,$A65)=0,"",_xlfn.MINIFS(Registro!$A$2:$A$1501,Registro!$C$2:$C$1501,$A65)) | E65: =IF($A65="","",COUNTIFS(Registro!$C$2:$C$1501,$A65,Registro!$E$2:$E$1501,">0")) | F65: =IF($A65="","",SUMIFS(Registro!$E$2:$E$1501,Registro!$C$2:$C$1501,$A65,Registro!$B$2:$B$1501,"Test ABO")) | G65: =IF($A65="","",F65/CPA_BE) | H65: =IF($A65="","",SUMIFS(Registro!$H$2:$H$1501,Registro!$C$2:$C$1501,$A65,Registro!$B$2:$B$1501,"Test ABO")) | I65: =IF(N(H65)>0,F65/H65,"") | J65: =IF(N(H65)>0,I65/CPA_BE-1,"") | K65: =IF(N(F65)>0,SUMIFS(Registro!$I$2:$I$1501,Registro!$C$2:$C$1501,$A65,Registro!$B$2:$B$1501,"Test ABO")/F65,"") | L65: =IF(N(F65)>0,SUMIFS(Registro!$I$2:$I$1501,Registro!$C$2:$C$1501,$A65,Registro!$B$2:$B$1501,"Test ABO")*(1-COM-COM_SHOP)-F65*(1+IMP_META),"") | M65: =IF(SUMIFS(Registro!$F$2:$F$1501,Registro!$C$2:$C$1501,$A65,Registro!$B$2:$B$1501,"Test ABO")>0,SUMIFS(Registro!$G$2:$G$1501,Registro!$C$2:$C$1501,$A65,Registro!$B$2:$B$1501,"Test ABO")/SUMIFS(Registro!$F$2:$F$1501,Registro!$C$2:$C$1501,$A65,Registro!$B$2:$B$1501,"Test ABO"),"") | N65: =IF($A65="","",IF(N(F65)=0,"Sin datos",IF(AND(H65>=MIN_VENTAS,N(I65)<=CPA_BE),"GANADOR → pasar a CBO",IF(AND(H65=0,F65>=K_SIN_VENTA*CPA_BE),"APAGAR (sin ventas)",IF(AND(H65>0,F65>=K_CARO*CPA_BE,N(I65)>CPA_BE*(1+TOL)),"APAGAR (CPA alto)",IF(AND(H65>0,N(I65)<=CPA_BE*(1+TOL)),"Prometedor / cerca del BE","Juntando datos")))))) | O65: =IF($A65="","",SUMIFS(Registro!$E$2:$E$1501,Registro!$C$2:$C$1501,$A65,Registro!$B$2:$B$1501,"Escala CBO")) | P65: =IF($A65="","",SUMIFS(Registro!$H$2:$H$1501,Registro!$C$2:$C$1501,$A65,Registro!$B$2:$B$1501,"Escala CBO")) | Q65: =IF(N(P65)>0,O65/P65,"") | R65: =IF(N(O65)>0,SUMIFS(Registro!$I$2:$I$1501,Registro!$C$2:$C$1501,$A65,Registro!$B$2:$B$1501,"Escala CBO")/O65,"") | S65: =IF(N(O65)>0,SUMIFS(Registro!$I$2:$I$1501,Registro!$C$2:$C$1501,$A65,Registro!$B$2:$B$1501,"Escala CBO")*(1-COM-COM_SHOP)-O65*(1+IMP_META),"") | T65: =IF(N(O65)=0,"",IF(P65=0,IF(O65>=K_SIN_VENTA*CPA_BE,"Sin ventas: revisar","Juntando datos"),IF(Q65<=CPA_BE,"Rentable","No rentable"))) | U65: =IF($A65="","",N(L65)+N(S65))

Sheet Configuración
A1: Configuración
A3: PRECIOS | B3: Precio | C3: % de las ventas (estimado)
A4: Básico | B4: 14900 | C4: 0.4 | D4: Precios sacados de la landing. El % es una estimación: ajustalo cuando veas cómo se reparten las ventas.
A5: Premium con descuento (upsell) | B5: 17900 | C5: 0.25
A6: Premium precio lleno | B6: 19900 | C6: 0.35
A7: Ticket promedio estimado | B7: =SUMPRODUCT(B4:B6,C4:C6)/SUM(C4:C6) | D7: Promedio ponderado de los precios de arriba.
A8: Ticket promedio real (de lo cargado) | B8: =IF(SUM(Registro!$H$2:$H$1501)>0,SUM(Registro!$I$2:$I$1501)/SUM(Registro!$H$2:$H$1501),"") | D8: Valor de compras / compras, según lo que cargás en Registro.
A9: Compras mínimas para usar el ticket real | B9: 10 | D9: Con pocas ventas el promedio real es poco confiable; hasta entonces se usa el estimado.
A10: Ticket usado en los cálculos | B10: =IF(SUM(Registro!$H$2:$H$1501)>=B9,B8,B7)
A12: Comisión Mercado Pago | B12: 0.0761 | D12: Estimado: 6,29% + IVA (acreditación inmediata). Verificalo en tu cuenta de Mercado Pago > Costos.
A13: Comisión Shopify por pasarela externa | B13: 0.02 | D13: Shopify cobra un % extra si no usás Shopify Payments (2% en plan Basic). Verificá tu plan.
A14: Impuestos que Meta suma al gasto | B14: 0.21 | D14: Estimado: IVA 21%. Mirá una factura de Meta: si hay percepciones, sumalas. Si sos Responsable Inscripto y recuperás el IVA, poné 0%.
A16: COSTO POR VENTA DE EQUILIBRIO (CPA BE) | B16: =B10*(1-B12-B13)/(1+B14) | D16: Lo máximo que podés pagar por venta (medido como lo muestra Meta, sin impuestos) sin perder plata.
A17: ROAS de equilibrio | B17: =(1+B14)/(1-B12-B13) | D17: Por encima de este ROAS (el que muestra Meta) ganás plata.
A19: REGLAS DE DECISIÓN DEL TEST (por anuncio)
A20: Ventas mínimas para declarar GANADOR | B20: 2 | D20: Ganador = al menos estas ventas y CPA ≤ CPA BE.
A21: APAGAR si gastó esto sin ninguna venta (veces el CPA BE) | B21: 1.5 | D21: Ej.: 1,5x = gastó 1,5 veces el CPA BE y no vendió nada.
A22: APAGAR por caro: a partir de este gasto (veces el CPA BE)… | B22: 2
A23: …si el CPA supera el CPA BE en más de | B23: 0.3 | D23: También define el margen de 'Prometedor / cerca del BE'.
A25: ÁNGULOS DE VENTA (uno por fila)
A26: Ahorro de tiempo
A27: Resultados en los chicos
A28: Autoridad musicoterapeuta
A43: CÓMO SE USA
A44: Celdas amarillas con texto azul = las completás vos. Texto negro = fórmulas, no tocar.
A45: 1) Cargá tus ángulos acá y tus anuncios en la hoja 'Anuncios' (nombre + ángulo).
A46: 2) Todos los días, en 'Registro', una fila por anuncio con los datos de ayer del Administrador de anuncios.
A47: 3) Mirá la columna ESTADO en 'Anuncios': te dice qué apagar y qué pasar a la campaña CBO.
A48: Las filas de ejemplo (3 anuncios y sus registros) son de muestra: borralas antes de empezar.

Sheet Registro
A1: Fecha | B1: Fase | C1: Anuncio | D1: Ángulo | E1: Gasto (Meta) | F1: Impresiones | G1: Clics en el enlace | H1: Compras | I1: Valor de compras | J1: CTR | K1: CPC | L1: CPA | M1: ROAS | N1: Ganancia neta | O1: Notas
A2: 46286 | B2: Test ABO | C2: AD01 - Ahorro de tiempo | D2: =IF(C2="","",IFERROR(INDEX(Anuncios!$B$6:$B$65,MATCH(C2,Anuncios!$A$6:$A$65,0)),"(no está en Anuncios)")) | E2: 10000 | F2: 9500 | G2: 140 | H2: 1 | I2: 17900 | J2: =IF(N(F2)>0,G2/F2,"") | K2: =IF(N(G2)>0,E2/G2,"") | L2: =IF(N(H2)>0,E2/H2,"") | M2: =IF(N(E2)>0,I2/E2,"") | N2: =IF(AND(E2="",I2=""),"",N(I2)*(1-COM-COM_SHOP)-N(E2)*(1+IMP_META)) | O2: EJEMPLO: borrar
A3: 46287 | B3: Test ABO | C3: AD01 - Ahorro de tiempo | D3: =IF(C3="","",IFERROR(INDEX(Anuncios!$B$6:$B$65,MATCH(C3,Anuncios!$A$6:$A$65,0)),"(no está en Anuncios)")) | E3: 10000 | F3: 9800 | G3: 150 | H3: 1 | I3: 14900 | J3: =IF(N(F3)>0,G3/F3,"") | K3: =IF(N(G3)>0,E3/G3,"") | L3: =IF(N(H3)>0,E3/H3,"") | M3: =IF(N(E3)>0,I3/E3,"") | N3: =IF(AND(E3="",I3=""),"",N(I3)*(1-COM-COM_SHOP)-N(E3)*(1+IMP_META)) | O3: EJEMPLO: borrar
A4: 46288 | B4: Test ABO | C4: AD01 - Ahorro de tiempo | D4: =IF(C4="","",IFERROR(INDEX(Anuncios!$B$6:$B$65,MATCH(C4,Anuncios!$A$6:$A$65,0)),"(no está en Anuncios)")) | E4: 10000 | F4: 10100 | G4: 160 | H4: 1 | I4: 19900 | J4: =IF(N(F4)>0,G4/F4,"") | K4: =IF(N(G4)>0,E4/G4,"") | L4: =IF(N(H4)>0,E4/H4,"") | M4: =IF(N(E4)>0,I4/E4,"") | N4: =IF(AND(E4="",I4=""),"",N(I4)*(1-COM-COM_SHOP)-N(E4)*(1+IMP_META)) | O4: EJEMPLO: borrar
A5: 46286 | B5: Test ABO | C5: AD02 - Resultados en los chicos | D5: =IF(C5="","",IFERROR(INDEX(Anuncios!$B$6:$B$65,MATCH(C5,Anuncios!$A$6:$A$65,0)),"(no está en Anuncios)")) | E5: 10000 | F5: 11000 | G5: 90 | H5: 0 | I5: 0 | J5: =IF(N(F5)>0,G5/F5,"") | K5: =IF(N(G5)>0,E5/G5,"") | L5: =IF(N(H5)>0,E5/H5,"") | M5: =IF(N(E5)>0,I5/E5,"") | N5: =IF(AND(E5="",I5=""),"",N(I5)*(1-COM-COM_SHOP)-N(E5)*(1+IMP_META)) | O5: EJEMPLO: borrar
A6: 46287 | B6: Test ABO | C6: AD02 - Resultados en los chicos | D6: =IF(C6="","",IFERROR(INDEX(Anuncios!$B$6:$B$65,MATCH(C6,Anuncios!$A$6:$A$65,0)),"(no está en Anuncios)")) | E6: 10000 | F6: 10500 | G6: 85 | H6: 0 | I6: 0 | J6: =IF(N(F6)>0,G6/F6,"") | K6: =IF(N(G6)>0,E6/G6,"") | L6: =IF(N(H6)>0,E6/H6,"") | M6: =IF(N(E6)>0,I6/E6,"") | N6: =IF(AND(E6="",I6=""),"",N(I6)*(1-COM-COM_SHOP)-N(E6)*(1+IMP_META)) | O6: EJEMPLO: borrar
A7: 46288 | B7: Test ABO | C7: AD03 - Autoridad musicoterapeuta | D7: =IF(C7="","",IFERROR(INDEX(Anuncios!$B$6:$B$65,MATCH(C7,Anuncios!$A$6:$A$65,0)),"(no está en Anuncios)")) | E7: 10000 | F7: 8700 | G7: 120 | H7: 1 | I7: 17900 | J7: =IF(N(F7)>0,G7/F7,"") | K7: =IF(N(G7)>0,E7/G7,"") | L7: =IF(N(H7)>0,E7/H7,"") | M7: =IF(N(E7)>0,I7/E7,"") | N7: =IF(AND(E7="",I7=""),"",N(I7)*(1-COM-COM_SHOP)-N(E7)*(1+IMP_META)) | O7: EJEMPLO: borrar
A8: 46290 | B8: Escala CBO | C8: AD01 - Ahorro de tiempo | D8: =IF(C8="","",IFERROR(INDEX(Anuncios!$B$6:$B$65,MATCH(C8,Anuncios!$A$6:$A$65,0)),"(no está en Anuncios)")) | E8: 25000 | F8: 24000 | G8: 380 | H8: 2 | I8: 37800 | J8: =IF(N(F8)>0,G8/F8,"") | K8: =IF(N(G8)>0,E8/G8,"") | L8: =IF(N(H8)>0,E8/H8,"") | M8: =IF(N(E8)>0,I8/E8,"") | N8: =IF(AND(E8="",I8=""),"",N(I8)*(1-COM-COM_SHOP)-N(E8)*(1+IMP_META)) | O8: EJEMPLO: borrar
